2023-05-30 14:23:55
Traceback (most recent call last):
  File "D:\local_repo\CTA_UI\start.py", line 793, in <module>
    ex = Example()
  File "D:\local_repo\CTA_UI\start.py", line 31, in __init__
    self.param = paraTable()
  File "D:\local_repo\CTA_UI\UI_widget\paraTable.py", line 28, in __init__
    self.model = pandasModel.pandasModel(info_df)
AttributeError: type object 'pandasModel' has no attribute 'pandasModel'

2023-05-30 14:26:24
Traceback (most recent call last):
  File "D:\local_repo\CTA_UI\start.py", line 793, in <module>
    ex = Example()
  File "D:\local_repo\CTA_UI\start.py", line 31, in __init__
    self.param = paraTable()
  File "D:\local_repo\CTA_UI\UI_widget\paraTable.py", line 28, in __init__
    self.model = pandasModel.pandasModel(info_df)
AttributeError: type object 'pandasModel' has no attribute 'pandasModel'

2023-05-30 14:26:43
Traceback (most recent call last):
  File "D:\local_repo\CTA_UI\start.py", line 793, in <module>
    ex = Example()
  File "D:\local_repo\CTA_UI\start.py", line 31, in __init__
    self.param = paraTable()
  File "D:\local_repo\CTA_UI\UI_widget\paraTable.py", line 28, in __init__
    self.model = pandasModel.pandasModel(info_df)
AttributeError: type object 'pandasModel' has no attribute 'pandasModel'

2023-05-30 14:27:04
Traceback (most recent call last):
  File "D:\local_repo\CTA_UI\start.py", line 793, in <module>
    ex = Example()
  File "D:\local_repo\CTA_UI\start.py", line 31, in __init__
    self.param = paraTable()
  File "D:\local_repo\CTA_UI\UI_widget\paraTable.py", line 29, in __init__
    self.model = pandasModel.pandasModel(info_df)
AttributeError: type object 'pandasModel' has no attribute 'pandasModel'

2023-05-30 14:27:33
Traceback (most recent call last):
  File "D:\local_repo\CTA_UI\start.py", line 793, in <module>
    ex = Example()
  File "D:\local_repo\CTA_UI\start.py", line 31, in __init__
    self.param = paraTable()
  File "D:\local_repo\CTA_UI\UI_widget\paraTable.py", line 30, in __init__
    self.model = pandasModel.pandasModel(info_df)
AttributeError: type object 'pandasModel' has no attribute 'pandasModel'

2023-05-30 14:28:28
Traceback (most recent call last):
  File "D:\local_repo\CTA_UI\start.py", line 793, in <module>
    ex = Example()
  File "D:\local_repo\CTA_UI\start.py", line 31, in __init__
    self.param = paraTable()
  File "D:\local_repo\CTA_UI\UI_widget\paraTable.py", line 30, in __init__
    self.model = pandasModel.pandasModel(info_df)
AttributeError: type object 'pandasModel' has no attribute 'pandasModel'

2023-05-30 14:29:00
Traceback (most recent call last):
  File "D:\local_repo\CTA_UI\start.py", line 793, in <module>
    ex = Example()
  File "D:\local_repo\CTA_UI\start.py", line 31, in __init__
    self.param = paraTable()
  File "D:\local_repo\CTA_UI\UI_widget\paraTable.py", line 29, in __init__
    self.model = pandasModel(info_df)
  File "D:\local_repo\CTA_UI\UI_widget\pandasModel.py", line 30, in __init__
    self._data = self.addColumnToDf(data, barplot_flag, checkbox_flag)
  File "D:\local_repo\CTA_UI\UI_widget\pandasModel.py", line 34, in addColumnToDf
    data.insert(0, 'BarPlot', data.apply(lambda x: pairname_to_plotdir(x.name), axis=1))
  File "C:\Users\Han.Hao\AppData\Local\anaconda3\lib\site-packages\pandas\core\frame.py", line 9568, in apply
    return op.apply().__finalize__(self, method="apply")
  File "C:\Users\Han.Hao\AppData\Local\anaconda3\lib\site-packages\pandas\core\apply.py", line 764, in apply
    return self.apply_standard()
  File "C:\Users\Han.Hao\AppData\Local\anaconda3\lib\site-packages\pandas\core\apply.py", line 891, in apply_standard
    results, res_index = self.apply_series_generator()
  File "C:\Users\Han.Hao\AppData\Local\anaconda3\lib\site-packages\pandas\core\apply.py", line 907, in apply_series_generator
    results[i] = self.f(v)
  File "D:\local_repo\CTA_UI\UI_widget\pandasModel.py", line 34, in <lambda>
    data.insert(0, 'BarPlot', data.apply(lambda x: pairname_to_plotdir(x.name), axis=1))
  File "D:\local_repo\CTA_UI\utils\plotfile_management.py", line 15, in pairname_to_plotdir
    plotname = date + "-" + contract_pair_name + ".png"
TypeError: can only concatenate str (not "int") to str

2023-05-30 14:29:36
Traceback (most recent call last):
  File "D:\local_repo\CTA_UI\start.py", line 793, in <module>
    ex = Example()
  File "D:\local_repo\CTA_UI\start.py", line 31, in __init__
    self.param = paraTable()
  File "D:\local_repo\CTA_UI\UI_widget\paraTable.py", line 29, in __init__
    self.model = pandasModel(info_df)
  File "D:\local_repo\CTA_UI\UI_widget\pandasModel.py", line 31, in __init__
    self._data = self.addColumnToDf(data, barplot_flag, checkbox_flag)
  File "D:\local_repo\CTA_UI\UI_widget\pandasModel.py", line 35, in addColumnToDf
    data.insert(0, 'BarPlot', data.apply(lambda x: pairname_to_plotdir(x.name), axis=1))
  File "C:\Users\Han.Hao\AppData\Local\anaconda3\lib\site-packages\pandas\core\frame.py", line 9568, in apply
    return op.apply().__finalize__(self, method="apply")
  File "C:\Users\Han.Hao\AppData\Local\anaconda3\lib\site-packages\pandas\core\apply.py", line 764, in apply
    return self.apply_standard()
  File "C:\Users\Han.Hao\AppData\Local\anaconda3\lib\site-packages\pandas\core\apply.py", line 891, in apply_standard
    results, res_index = self.apply_series_generator()
  File "C:\Users\Han.Hao\AppData\Local\anaconda3\lib\site-packages\pandas\core\apply.py", line 907, in apply_series_generator
    results[i] = self.f(v)
  File "D:\local_repo\CTA_UI\UI_widget\pandasModel.py", line 35, in <lambda>
    data.insert(0, 'BarPlot', data.apply(lambda x: pairname_to_plotdir(x.name), axis=1))
  File "D:\local_repo\CTA_UI\utils\plotfile_management.py", line 15, in pairname_to_plotdir
    plotname = date + "-" + contract_pair_name + ".png"
TypeError: can only concatenate str (not "int") to str

2023-05-30 14:30:01
Traceback (most recent call last):
  File "D:\local_repo\CTA_UI\start.py", line 793, in <module>
    ex = Example()
  File "D:\local_repo\CTA_UI\start.py", line 31, in __init__
    self.param = paraTable()
  File "D:\local_repo\CTA_UI\UI_widget\paraTable.py", line 29, in __init__
    self.model = pandasModel(info_df)
  File "D:\local_repo\CTA_UI\UI_widget\pandasModel.py", line 30, in __init__
    self._data = self.addColumnToDf(data, barplot_flag, checkbox_flag)
  File "D:\local_repo\CTA_UI\UI_widget\pandasModel.py", line 34, in addColumnToDf
    data.insert(0, 'BarPlot', data.apply(lambda x: pairname_to_plotdir(x.name), axis=1))
  File "C:\Users\Han.Hao\AppData\Local\anaconda3\lib\site-packages\pandas\core\frame.py", line 9568, in apply
    return op.apply().__finalize__(self, method="apply")
  File "C:\Users\Han.Hao\AppData\Local\anaconda3\lib\site-packages\pandas\core\apply.py", line 764, in apply
    return self.apply_standard()
  File "C:\Users\Han.Hao\AppData\Local\anaconda3\lib\site-packages\pandas\core\apply.py", line 891, in apply_standard
    results, res_index = self.apply_series_generator()
  File "C:\Users\Han.Hao\AppData\Local\anaconda3\lib\site-packages\pandas\core\apply.py", line 907, in apply_series_generator
    results[i] = self.f(v)
  File "D:\local_repo\CTA_UI\UI_widget\pandasModel.py", line 34, in <lambda>
    data.insert(0, 'BarPlot', data.apply(lambda x: pairname_to_plotdir(x.name), axis=1))
  File "D:\local_repo\CTA_UI\utils\plotfile_management.py", line 15, in pairname_to_plotdir
    plotname = date + "-" + contract_pair_name + ".png"
TypeError: can only concatenate str (not "int") to str

2023-05-30 14:30:36
Traceback (most recent call last):
  File "D:\local_repo\CTA_UI\start.py", line 793, in <module>
    ex = Example()
  File "D:\local_repo\CTA_UI\start.py", line 31, in __init__
    self.param = paraTable()
  File "D:\local_repo\CTA_UI\UI_widget\paraTable.py", line 29, in __init__
    self.model = pandasModel(info_df)
  File "D:\local_repo\CTA_UI\UI_widget\pandasModel.py", line 31, in __init__
    self._data = self.addColumnToDf(data, barplot_flag, checkbox_flag)
  File "D:\local_repo\CTA_UI\UI_widget\pandasModel.py", line 35, in addColumnToDf
    data.insert(0, 'BarPlot', data.apply(lambda x: pairname_to_plotdir(x.name), axis=1))
  File "C:\Users\Han.Hao\AppData\Local\anaconda3\lib\site-packages\pandas\core\frame.py", line 9568, in apply
    return op.apply().__finalize__(self, method="apply")
  File "C:\Users\Han.Hao\AppData\Local\anaconda3\lib\site-packages\pandas\core\apply.py", line 764, in apply
    return self.apply_standard()
  File "C:\Users\Han.Hao\AppData\Local\anaconda3\lib\site-packages\pandas\core\apply.py", line 891, in apply_standard
    results, res_index = self.apply_series_generator()
  File "C:\Users\Han.Hao\AppData\Local\anaconda3\lib\site-packages\pandas\core\apply.py", line 907, in apply_series_generator
    results[i] = self.f(v)
  File "D:\local_repo\CTA_UI\UI_widget\pandasModel.py", line 35, in <lambda>
    data.insert(0, 'BarPlot', data.apply(lambda x: pairname_to_plotdir(x.name), axis=1))
  File "D:\local_repo\CTA_UI\utils\plotfile_management.py", line 15, in pairname_to_plotdir
    plotname = date + "-" + contract_pair_name + ".png"
TypeError: can only concatenate str (not "int") to str

2023-05-30 16:07:58
Traceback (most recent call last):
  File "D:\local_repo\CTA_UI\start.py", line 793, in <module>
    ex = Example()
  File "D:\local_repo\CTA_UI\start.py", line 31, in __init__
    self.param = paraTable()
  File "D:\local_repo\CTA_UI\UI_widget\paraTable.py", line 19, in __init__
    self.model = pandasModel(info_df)
  File "D:\local_repo\CTA_UI\UI_widget\pandasModel.py", line 30, in __init__
    self._data = self.addColumnToDf(data, barplot_flag, checkbox_flag)
  File "D:\local_repo\CTA_UI\UI_widget\pandasModel.py", line 34, in addColumnToDf
    data.insert(0, 'BarPlot', data.apply(lambda x: pairname_to_plotdir(x.name), axis=1))
  File "C:\Users\Han.Hao\AppData\Local\anaconda3\lib\site-packages\pandas\core\frame.py", line 9568, in apply
    return op.apply().__finalize__(self, method="apply")
  File "C:\Users\Han.Hao\AppData\Local\anaconda3\lib\site-packages\pandas\core\apply.py", line 764, in apply
    return self.apply_standard()
  File "C:\Users\Han.Hao\AppData\Local\anaconda3\lib\site-packages\pandas\core\apply.py", line 891, in apply_standard
    results, res_index = self.apply_series_generator()
  File "C:\Users\Han.Hao\AppData\Local\anaconda3\lib\site-packages\pandas\core\apply.py", line 907, in apply_series_generator
    results[i] = self.f(v)
  File "D:\local_repo\CTA_UI\UI_widget\pandasModel.py", line 34, in <lambda>
    data.insert(0, 'BarPlot', data.apply(lambda x: pairname_to_plotdir(x.name), axis=1))
  File "D:\local_repo\CTA_UI\utils\plotfile_management.py", line 15, in pairname_to_plotdir
    plotname = date + "-" + contract_pair_name + ".png"
TypeError: can only concatenate str (not "int") to str

2023-05-30 16:08:21
Traceback (most recent call last):
  File "D:\local_repo\CTA_UI\start.py", line 793, in <module>
    ex = Example()
  File "D:\local_repo\CTA_UI\start.py", line 31, in __init__
    self.param = paraTable()
  File "D:\local_repo\CTA_UI\UI_widget\paraTable.py", line 20, in __init__
    self.model = pandasModel(info_df)
  File "D:\local_repo\CTA_UI\UI_widget\pandasModel.py", line 30, in __init__
    self._data = self.addColumnToDf(data, barplot_flag, checkbox_flag)
  File "D:\local_repo\CTA_UI\UI_widget\pandasModel.py", line 34, in addColumnToDf
    data.insert(0, 'BarPlot', data.apply(lambda x: pairname_to_plotdir(x.name), axis=1))
  File "C:\Users\Han.Hao\AppData\Local\anaconda3\lib\site-packages\pandas\core\frame.py", line 9568, in apply
    return op.apply().__finalize__(self, method="apply")
  File "C:\Users\Han.Hao\AppData\Local\anaconda3\lib\site-packages\pandas\core\apply.py", line 764, in apply
    return self.apply_standard()
  File "C:\Users\Han.Hao\AppData\Local\anaconda3\lib\site-packages\pandas\core\apply.py", line 891, in apply_standard
    results, res_index = self.apply_series_generator()
  File "C:\Users\Han.Hao\AppData\Local\anaconda3\lib\site-packages\pandas\core\apply.py", line 907, in apply_series_generator
    results[i] = self.f(v)
  File "D:\local_repo\CTA_UI\UI_widget\pandasModel.py", line 34, in <lambda>
    data.insert(0, 'BarPlot', data.apply(lambda x: pairname_to_plotdir(x.name), axis=1))
  File "D:\local_repo\CTA_UI\utils\plotfile_management.py", line 15, in pairname_to_plotdir
    plotname = date + "-" + contract_pair_name + ".png"
TypeError: can only concatenate str (not "int") to str

2023-05-30 16:08:59
Traceback (most recent call last):
  File "D:\local_repo\CTA_UI\start.py", line 793, in <module>
    ex = Example()
  File "D:\local_repo\CTA_UI\start.py", line 31, in __init__
    self.param = paraTable()
  File "D:\local_repo\CTA_UI\UI_widget\paraTable.py", line 20, in __init__
    self.model = pandasModel(info_df)
  File "D:\local_repo\CTA_UI\UI_widget\pandasModel.py", line 30, in __init__
    self._data = self.addColumnToDf(data, barplot_flag, checkbox_flag)
  File "D:\local_repo\CTA_UI\UI_widget\pandasModel.py", line 34, in addColumnToDf
    data.insert(0, 'BarPlot', data.apply(lambda x: pairname_to_plotdir(x.name), axis=1))
  File "C:\Users\Han.Hao\AppData\Local\anaconda3\lib\site-packages\pandas\core\frame.py", line 9568, in apply
    return op.apply().__finalize__(self, method="apply")
  File "C:\Users\Han.Hao\AppData\Local\anaconda3\lib\site-packages\pandas\core\apply.py", line 764, in apply
    return self.apply_standard()
  File "C:\Users\Han.Hao\AppData\Local\anaconda3\lib\site-packages\pandas\core\apply.py", line 891, in apply_standard
    results, res_index = self.apply_series_generator()
  File "C:\Users\Han.Hao\AppData\Local\anaconda3\lib\site-packages\pandas\core\apply.py", line 907, in apply_series_generator
    results[i] = self.f(v)
  File "D:\local_repo\CTA_UI\UI_widget\pandasModel.py", line 34, in <lambda>
    data.insert(0, 'BarPlot', data.apply(lambda x: pairname_to_plotdir(x.name), axis=1))
  File "D:\local_repo\CTA_UI\utils\plotfile_management.py", line 15, in pairname_to_plotdir
    plotname = date + "-" + contract_pair_name + ".png"
TypeError: can only concatenate str (not "int") to str

2023-05-30 16:31:20
Traceback (most recent call last):
  File "C:\Users\Han.Hao\AppData\Local\anaconda3\lib\site-packages\pandas\core\indexes\base.py", line 3802, in get_loc
    return self._engine.get_loc(casted_key)
  File "pandas\_libs\index.pyx", line 138, in pandas._libs.index.IndexEngine.get_loc
  File "pandas\_libs\index.pyx", line 165, in pandas._libs.index.IndexEngine.get_loc
  File "pandas\_libs\hashtable_class_helper.pxi", line 5745, in pandas._libs.hashtable.PyObjectHashTable.get_item
  File "pandas\_libs\hashtable_class_helper.pxi", line 5753, in pandas._libs.hashtable.PyObjectHashTable.get_item
KeyError: ('pairs_id', 'region_drift', 'region_0', 'region_1', 'region_2', 'region_3', 'region_4', 'region_5', 'region_6', 'region_7', 'region_tick_lock', 'region_unit_num')

The above exception was the direct cause of the following exception:

Traceback (most recent call last):
  File "D:\local_repo\CTA_UI\start.py", line 793, in <module>
    ex = Example()
  File "D:\local_repo\CTA_UI\start.py", line 31, in __init__
    self.param = paraTable()
  File "D:\local_repo\CTA_UI\UI_widget\paraTable.py", line 19, in __init__
    region_info, boundary_info, suffix_info = param_split(info_df)
  File "D:\local_repo\CTA_UI\utils\transform.py", line 40, in param_split
    region_df = df["pairs_id", "region_drift", "region_0", "region_1", "region_2", "region_3", "region_4", "region_5", "region_6", "region_7", "region_tick_lock" , "region_unit_num"]
  File "C:\Users\Han.Hao\AppData\Local\anaconda3\lib\site-packages\pandas\core\frame.py", line 3807, in __getitem__
    indexer = self.columns.get_loc(key)
  File "C:\Users\Han.Hao\AppData\Local\anaconda3\lib\site-packages\pandas\core\indexes\base.py", line 3804, in get_loc
    raise KeyError(key) from err
KeyError: ('pairs_id', 'region_drift', 'region_0', 'region_1', 'region_2', 'region_3', 'region_4', 'region_5', 'region_6', 'region_7', 'region_tick_lock', 'region_unit_num')

2023-05-30 16:31:40
Traceback (most recent call last):
  File "C:\Users\Han.Hao\AppData\Local\anaconda3\lib\site-packages\pandas\core\indexes\base.py", line 3802, in get_loc
    return self._engine.get_loc(casted_key)
  File "pandas\_libs\index.pyx", line 138, in pandas._libs.index.IndexEngine.get_loc
  File "pandas\_libs\index.pyx", line 165, in pandas._libs.index.IndexEngine.get_loc
  File "pandas\_libs\hashtable_class_helper.pxi", line 5745, in pandas._libs.hashtable.PyObjectHashTable.get_item
  File "pandas\_libs\hashtable_class_helper.pxi", line 5753, in pandas._libs.hashtable.PyObjectHashTable.get_item
KeyError: ('pairs_id', 'region_drift', 'region_0', 'region_1', 'region_2', 'region_3', 'region_4', 'region_5', 'region_6', 'region_7', 'region_tick_lock', 'region_unit_num')

The above exception was the direct cause of the following exception:

Traceback (most recent call last):
  File "D:\local_repo\CTA_UI\start.py", line 793, in <module>
    ex = Example()
  File "D:\local_repo\CTA_UI\start.py", line 31, in __init__
    self.param = paraTable()
  File "D:\local_repo\CTA_UI\UI_widget\paraTable.py", line 20, in __init__
    region_info, boundary_info, suffix_info = param_split(info_df)
  File "D:\local_repo\CTA_UI\utils\transform.py", line 40, in param_split
    region_df = df["pairs_id", "region_drift", "region_0", "region_1", "region_2", "region_3", "region_4", "region_5", "region_6", "region_7", "region_tick_lock" , "region_unit_num"]
  File "C:\Users\Han.Hao\AppData\Local\anaconda3\lib\site-packages\pandas\core\frame.py", line 3807, in __getitem__
    indexer = self.columns.get_loc(key)
  File "C:\Users\Han.Hao\AppData\Local\anaconda3\lib\site-packages\pandas\core\indexes\base.py", line 3804, in get_loc
    raise KeyError(key) from err
KeyError: ('pairs_id', 'region_drift', 'region_0', 'region_1', 'region_2', 'region_3', 'region_4', 'region_5', 'region_6', 'region_7', 'region_tick_lock', 'region_unit_num')

2023-05-30 16:32:09
Traceback (most recent call last):
  File "C:\Users\Han.Hao\AppData\Local\anaconda3\lib\site-packages\pandas\core\indexes\base.py", line 3802, in get_loc
    return self._engine.get_loc(casted_key)
  File "pandas\_libs\index.pyx", line 138, in pandas._libs.index.IndexEngine.get_loc
  File "pandas\_libs\index.pyx", line 165, in pandas._libs.index.IndexEngine.get_loc
  File "pandas\_libs\hashtable_class_helper.pxi", line 5745, in pandas._libs.hashtable.PyObjectHashTable.get_item
  File "pandas\_libs\hashtable_class_helper.pxi", line 5753, in pandas._libs.hashtable.PyObjectHashTable.get_item
KeyError: ('pairs_id', 'region_drift', 'region_0', 'region_1', 'region_2', 'region_3', 'region_4', 'region_5', 'region_6', 'region_7', 'region_tick_lock', 'region_unit_num')

The above exception was the direct cause of the following exception:

Traceback (most recent call last):
  File "D:\local_repo\CTA_UI\start.py", line 793, in <module>
    ex = Example()
  File "D:\local_repo\CTA_UI\start.py", line 31, in __init__
    self.param = paraTable()
  File "D:\local_repo\CTA_UI\UI_widget\paraTable.py", line 19, in __init__
    region_info, boundary_info, suffix_info = param_split(info_df)
  File "D:\local_repo\CTA_UI\utils\transform.py", line 40, in param_split
    region_df = df["pairs_id", "region_drift", "region_0", "region_1", "region_2", "region_3", "region_4", "region_5", "region_6", "region_7", "region_tick_lock" , "region_unit_num"]
  File "C:\Users\Han.Hao\AppData\Local\anaconda3\lib\site-packages\pandas\core\frame.py", line 3807, in __getitem__
    indexer = self.columns.get_loc(key)
  File "C:\Users\Han.Hao\AppData\Local\anaconda3\lib\site-packages\pandas\core\indexes\base.py", line 3804, in get_loc
    raise KeyError(key) from err
KeyError: ('pairs_id', 'region_drift', 'region_0', 'region_1', 'region_2', 'region_3', 'region_4', 'region_5', 'region_6', 'region_7', 'region_tick_lock', 'region_unit_num')

2023-05-30 16:32:24
Traceback (most recent call last):
  File "C:\Users\Han.Hao\AppData\Local\anaconda3\lib\site-packages\pandas\core\indexes\base.py", line 3802, in get_loc
    return self._engine.get_loc(casted_key)
  File "pandas\_libs\index.pyx", line 138, in pandas._libs.index.IndexEngine.get_loc
  File "pandas\_libs\index.pyx", line 165, in pandas._libs.index.IndexEngine.get_loc
  File "pandas\_libs\hashtable_class_helper.pxi", line 5745, in pandas._libs.hashtable.PyObjectHashTable.get_item
  File "pandas\_libs\hashtable_class_helper.pxi", line 5753, in pandas._libs.hashtable.PyObjectHashTable.get_item
KeyError: ('pairs_id', 'region_drift', 'region_0', 'region_1', 'region_2', 'region_3', 'region_4', 'region_5', 'region_6', 'region_7', 'region_tick_lock', 'region_unit_num')

The above exception was the direct cause of the following exception:

Traceback (most recent call last):
  File "D:\local_repo\CTA_UI\start.py", line 793, in <module>
    ex = Example()
  File "D:\local_repo\CTA_UI\start.py", line 31, in __init__
    self.param = paraTable()
  File "D:\local_repo\CTA_UI\UI_widget\paraTable.py", line 20, in __init__
    region_info, boundary_info, suffix_info = param_split(info_df)
  File "D:\local_repo\CTA_UI\utils\transform.py", line 40, in param_split
    region_df = df["pairs_id", "region_drift", "region_0", "region_1", "region_2", "region_3", "region_4", "region_5", "region_6", "region_7", "region_tick_lock" , "region_unit_num"]
  File "C:\Users\Han.Hao\AppData\Local\anaconda3\lib\site-packages\pandas\core\frame.py", line 3807, in __getitem__
    indexer = self.columns.get_loc(key)
  File "C:\Users\Han.Hao\AppData\Local\anaconda3\lib\site-packages\pandas\core\indexes\base.py", line 3804, in get_loc
    raise KeyError(key) from err
KeyError: ('pairs_id', 'region_drift', 'region_0', 'region_1', 'region_2', 'region_3', 'region_4', 'region_5', 'region_6', 'region_7', 'region_tick_lock', 'region_unit_num')

2023-05-30 16:33:13
Traceback (most recent call last):
  File "C:\Users\Han.Hao\AppData\Local\anaconda3\lib\site-packages\pandas\core\indexes\base.py", line 3802, in get_loc
    return self._engine.get_loc(casted_key)
  File "pandas\_libs\index.pyx", line 138, in pandas._libs.index.IndexEngine.get_loc
  File "pandas\_libs\index.pyx", line 165, in pandas._libs.index.IndexEngine.get_loc
  File "pandas\_libs\hashtable_class_helper.pxi", line 5745, in pandas._libs.hashtable.PyObjectHashTable.get_item
  File "pandas\_libs\hashtable_class_helper.pxi", line 5753, in pandas._libs.hashtable.PyObjectHashTable.get_item
KeyError: ('pairs_id', 'region_drift', 'region_0', 'region_1', 'region_2', 'region_3', 'region_4', 'region_5', 'region_6', 'region_7', 'region_tick_lock', 'region_unit_num')

The above exception was the direct cause of the following exception:

Traceback (most recent call last):
  File "D:\local_repo\CTA_UI\start.py", line 793, in <module>
    ex = Example()
  File "D:\local_repo\CTA_UI\start.py", line 31, in __init__
    self.param = paraTable()
  File "D:\local_repo\CTA_UI\UI_widget\paraTable.py", line 19, in __init__
    region_info, boundary_info, suffix_info = param_split(info_df)
  File "D:\local_repo\CTA_UI\utils\transform.py", line 40, in param_split
    region_df = df["pairs_id", "region_drift", "region_0", "region_1", "region_2", "region_3", "region_4", "region_5", "region_6", "region_7", "region_tick_lock" , "region_unit_num"]
  File "C:\Users\Han.Hao\AppData\Local\anaconda3\lib\site-packages\pandas\core\frame.py", line 3807, in __getitem__
    indexer = self.columns.get_loc(key)
  File "C:\Users\Han.Hao\AppData\Local\anaconda3\lib\site-packages\pandas\core\indexes\base.py", line 3804, in get_loc
    raise KeyError(key) from err
KeyError: ('pairs_id', 'region_drift', 'region_0', 'region_1', 'region_2', 'region_3', 'region_4', 'region_5', 'region_6', 'region_7', 'region_tick_lock', 'region_unit_num')

2023-05-30 16:33:50
Traceback (most recent call last):
  File "C:\Users\Han.Hao\AppData\Local\anaconda3\lib\site-packages\pandas\core\indexes\base.py", line 3802, in get_loc
    return self._engine.get_loc(casted_key)
  File "pandas\_libs\index.pyx", line 138, in pandas._libs.index.IndexEngine.get_loc
  File "pandas\_libs\index.pyx", line 165, in pandas._libs.index.IndexEngine.get_loc
  File "pandas\_libs\hashtable_class_helper.pxi", line 5745, in pandas._libs.hashtable.PyObjectHashTable.get_item
  File "pandas\_libs\hashtable_class_helper.pxi", line 5753, in pandas._libs.hashtable.PyObjectHashTable.get_item
KeyError: ('region_drift', 'region_0', 'region_1', 'region_2', 'region_3', 'region_4', 'region_5', 'region_6', 'region_7', 'region_tick_lock', 'region_unit_num')

The above exception was the direct cause of the following exception:

Traceback (most recent call last):
  File "D:\local_repo\CTA_UI\start.py", line 793, in <module>
    ex = Example()
  File "D:\local_repo\CTA_UI\start.py", line 31, in __init__
    self.param = paraTable()
  File "D:\local_repo\CTA_UI\UI_widget\paraTable.py", line 19, in __init__
    region_info, boundary_info, suffix_info = param_split(info_df)
  File "D:\local_repo\CTA_UI\utils\transform.py", line 40, in param_split
    region_df = df["region_drift", "region_0", "region_1", "region_2", "region_3", "region_4", "region_5", "region_6", "region_7", "region_tick_lock" , "region_unit_num"]
  File "C:\Users\Han.Hao\AppData\Local\anaconda3\lib\site-packages\pandas\core\frame.py", line 3807, in __getitem__
    indexer = self.columns.get_loc(key)
  File "C:\Users\Han.Hao\AppData\Local\anaconda3\lib\site-packages\pandas\core\indexes\base.py", line 3804, in get_loc
    raise KeyError(key) from err
KeyError: ('region_drift', 'region_0', 'region_1', 'region_2', 'region_3', 'region_4', 'region_5', 'region_6', 'region_7', 'region_tick_lock', 'region_unit_num')

2023-05-30 16:34:03
Traceback (most recent call last):
  File "C:\Users\Han.Hao\AppData\Local\anaconda3\lib\site-packages\pandas\core\indexes\base.py", line 3802, in get_loc
    return self._engine.get_loc(casted_key)
  File "pandas\_libs\index.pyx", line 138, in pandas._libs.index.IndexEngine.get_loc
  File "pandas\_libs\index.pyx", line 165, in pandas._libs.index.IndexEngine.get_loc
  File "pandas\_libs\hashtable_class_helper.pxi", line 5745, in pandas._libs.hashtable.PyObjectHashTable.get_item
  File "pandas\_libs\hashtable_class_helper.pxi", line 5753, in pandas._libs.hashtable.PyObjectHashTable.get_item
KeyError: ('region_drift', 'region_0', 'region_1', 'region_2', 'region_3', 'region_4', 'region_5', 'region_6', 'region_7', 'region_tick_lock', 'region_unit_num')

The above exception was the direct cause of the following exception:

Traceback (most recent call last):
  File "D:\local_repo\CTA_UI\start.py", line 793, in <module>
    ex = Example()
  File "D:\local_repo\CTA_UI\start.py", line 31, in __init__
    self.param = paraTable()
  File "D:\local_repo\CTA_UI\UI_widget\paraTable.py", line 19, in __init__
    region_info, boundary_info, suffix_info = param_split(info_df)
  File "D:\local_repo\CTA_UI\utils\transform.py", line 41, in param_split
    region_df = df["region_drift", "region_0", "region_1", "region_2", "region_3", "region_4", "region_5", "region_6", "region_7", "region_tick_lock" , "region_unit_num"]
  File "C:\Users\Han.Hao\AppData\Local\anaconda3\lib\site-packages\pandas\core\frame.py", line 3807, in __getitem__
    indexer = self.columns.get_loc(key)
  File "C:\Users\Han.Hao\AppData\Local\anaconda3\lib\site-packages\pandas\core\indexes\base.py", line 3804, in get_loc
    raise KeyError(key) from err
KeyError: ('region_drift', 'region_0', 'region_1', 'region_2', 'region_3', 'region_4', 'region_5', 'region_6', 'region_7', 'region_tick_lock', 'region_unit_num')

2023-05-30 16:34:41
Traceback (most recent call last):
  File "C:\Users\Han.Hao\AppData\Local\anaconda3\lib\site-packages\pandas\core\indexes\base.py", line 3802, in get_loc
    return self._engine.get_loc(casted_key)
  File "pandas\_libs\index.pyx", line 138, in pandas._libs.index.IndexEngine.get_loc
  File "pandas\_libs\index.pyx", line 165, in pandas._libs.index.IndexEngine.get_loc
  File "pandas\_libs\hashtable_class_helper.pxi", line 5745, in pandas._libs.hashtable.PyObjectHashTable.get_item
  File "pandas\_libs\hashtable_class_helper.pxi", line 5753, in pandas._libs.hashtable.PyObjectHashTable.get_item
KeyError: ('region_drift', 'region_0', 'region_1', 'region_2', 'region_3', 'region_4', 'region_5', 'region_6', 'region_7', 'region_tick_lock', 'region_unit_num')

The above exception was the direct cause of the following exception:

Traceback (most recent call last):
  File "D:\local_repo\CTA_UI\start.py", line 793, in <module>
    ex = Example()
  File "D:\local_repo\CTA_UI\start.py", line 31, in __init__
    self.param = paraTable()
  File "D:\local_repo\CTA_UI\UI_widget\paraTable.py", line 19, in __init__
    region_info, boundary_info, suffix_info = param_split(info_df)
  File "D:\local_repo\CTA_UI\utils\transform.py", line 40, in param_split
    region_df = df["region_drift", "region_0", "region_1", "region_2", "region_3", "region_4", "region_5", "region_6", "region_7", "region_tick_lock" , "region_unit_num"]
  File "C:\Users\Han.Hao\AppData\Local\anaconda3\lib\site-packages\pandas\core\frame.py", line 3807, in __getitem__
    indexer = self.columns.get_loc(key)
  File "C:\Users\Han.Hao\AppData\Local\anaconda3\lib\site-packages\pandas\core\indexes\base.py", line 3804, in get_loc
    raise KeyError(key) from err
KeyError: ('region_drift', 'region_0', 'region_1', 'region_2', 'region_3', 'region_4', 'region_5', 'region_6', 'region_7', 'region_tick_lock', 'region_unit_num')

2023-05-30 16:36:36
Traceback (most recent call last):
  File "D:\local_repo\CTA_UI\start.py", line 793, in <module>
    ex = Example()
  File "D:\local_repo\CTA_UI\start.py", line 31, in __init__
    self.param = paraTable()
  File "D:\local_repo\CTA_UI\UI_widget\paraTable.py", line 19, in __init__
    region_info, boundary_info, suffix_info = param_split(info_df)
  File "D:\local_repo\CTA_UI\utils\transform.py", line 40, in param_split
    region_df = df.loc[:,"region_drift", "region_0", "region_1", "region_2", "region_3", "region_4", "region_5", "region_6", "region_7", "region_tick_lock" , "region_unit_num"]
  File "C:\Users\Han.Hao\AppData\Local\anaconda3\lib\site-packages\pandas\core\indexing.py", line 1067, in __getitem__
    return self._getitem_tuple(key)
  File "C:\Users\Han.Hao\AppData\Local\anaconda3\lib\site-packages\pandas\core\indexing.py", line 1250, in _getitem_tuple
    tup = self._validate_tuple_indexer(tup)
  File "C:\Users\Han.Hao\AppData\Local\anaconda3\lib\site-packages\pandas\core\indexing.py", line 869, in _validate_tuple_indexer
    key = self._validate_key_length(key)
  File "C:\Users\Han.Hao\AppData\Local\anaconda3\lib\site-packages\pandas\core\indexing.py", line 908, in _validate_key_length
    raise IndexingError("Too many indexers")
pandas.errors.IndexingError: Too many indexers

2023-05-31 10:36:40
Traceback (most recent call last):
  File "D:\local_repo\CTA_UI\start.py", line 793, in <module>
    ex = Example()
  File "D:\local_repo\CTA_UI\start.py", line 31, in __init__
    self.param = paraTable()
  File "D:\local_repo\CTA_UI\UI_widget\paraTable.py", line 24, in __init__
    self.model = self.model.updateHeaderSize()
  File "D:\local_repo\CTA_UI\UI_widget\pandasModel.py", line 43, in updateHeaderSize
    sizeHint = self.sizeHintForIndex(index)
AttributeError: 'pandasModel' object has no attribute 'sizeHintForIndex'

2023-05-31 10:39:06
Traceback (most recent call last):
  File "D:\local_repo\CTA_UI\start.py", line 793, in <module>
    ex = Example()
  File "D:\local_repo\CTA_UI\start.py", line 31, in __init__
    self.param = paraTable()
  File "D:\local_repo\CTA_UI\UI_widget\paraTable.py", line 24, in __init__
    self.model = self.model.updateHeaderSize()
  File "D:\local_repo\CTA_UI\UI_widget\pandasModel.py", line 43, in updateHeaderSize
    sizeHint = self.sizeHintForIndex(index)
AttributeError: 'pandasModel' object has no attribute 'sizeHintForIndex'

2023-05-31 10:39:35
Traceback (most recent call last):
  File "D:\local_repo\CTA_UI\start.py", line 793, in <module>
    ex = Example()
  File "D:\local_repo\CTA_UI\start.py", line 31, in __init__
    self.param = paraTable()
  File "D:\local_repo\CTA_UI\UI_widget\paraTable.py", line 24, in __init__
    self.model.updateHeaderSize()
  File "D:\local_repo\CTA_UI\UI_widget\pandasModel.py", line 43, in updateHeaderSize
    sizeHint = self.sizeHintForIndex(index)
AttributeError: 'pandasModel' object has no attribute 'sizeHintForIndex'

2023-05-31 10:42:39
Traceback (most recent call last):
  File "D:\local_repo\CTA_UI\start.py", line 793, in <module>
    ex = Example()
  File "D:\local_repo\CTA_UI\start.py", line 31, in __init__
    self.param = paraTable()
  File "D:\local_repo\CTA_UI\UI_widget\paraTable.py", line 24, in __init__
    self.model.updateHeaderSize()
  File "D:\local_repo\CTA_UI\UI_widget\pandasModel.py", line 43, in updateHeaderSize
    sizeHint = self.sizeHintForIndex(index)
AttributeError: 'pandasModel' object has no attribute 'sizeHintForIndex'

2023-05-31 10:44:51
Traceback (most recent call last):
  File "D:\local_repo\CTA_UI\start.py", line 793, in <module>
    ex = Example()
  File "D:\local_repo\CTA_UI\start.py", line 31, in __init__
    self.param = paraTable()
  File "D:\local_repo\CTA_UI\UI_widget\paraTable.py", line 25, in __init__
    self.model.updateHeaderSize()
  File "D:\local_repo\CTA_UI\UI_widget\pandasModel.py", line 43, in updateHeaderSize
    sizeHint = self.sizeHintForIndex(index)
AttributeError: 'pandasModel' object has no attribute 'sizeHintForIndex'

2023-05-31 10:45:03
Traceback (most recent call last):
  File "D:\local_repo\CTA_UI\start.py", line 793, in <module>
    ex = Example()
  File "D:\local_repo\CTA_UI\start.py", line 31, in __init__
    self.param = paraTable()
  File "D:\local_repo\CTA_UI\UI_widget\paraTable.py", line 25, in __init__
    self.model.updateHeaderSize()
  File "D:\local_repo\CTA_UI\UI_widget\pandasModel.py", line 44, in updateHeaderSize
    sizeHint = self.sizeHintForIndex(index)
AttributeError: 'pandasModel' object has no attribute 'sizeHintForIndex'

2023-05-31 10:45:27
Traceback (most recent call last):
  File "D:\local_repo\CTA_UI\start.py", line 793, in <module>
    ex = Example()
  File "D:\local_repo\CTA_UI\start.py", line 31, in __init__
    self.param = paraTable()
  File "D:\local_repo\CTA_UI\UI_widget\paraTable.py", line 25, in __init__
    self.model.updateHeaderSize()
  File "D:\local_repo\CTA_UI\UI_widget\pandasModel.py", line 43, in updateHeaderSize
    sizeHint = self.sizeHintForIndex(index)
AttributeError: 'pandasModel' object has no attribute 'sizeHintForIndex'

2023-05-31 10:46:03
Traceback (most recent call last):
  File "D:\local_repo\CTA_UI\start.py", line 793, in <module>
    ex = Example()
  File "D:\local_repo\CTA_UI\start.py", line 31, in __init__
    self.param = paraTable()
  File "D:\local_repo\CTA_UI\UI_widget\paraTable.py", line 25, in __init__
    self.model.updateHeaderSize()
  File "D:\local_repo\CTA_UI\UI_widget\pandasModel.py", line 45, in updateHeaderSize
    sizeHint = self.sizeHintForIndex(index)
AttributeError: 'pandasModel' object has no attribute 'sizeHintForIndex'

2023-05-31 10:46:23
Traceback (most recent call last):
  File "D:\local_repo\CTA_UI\start.py", line 793, in <module>
    ex = Example()
  File "D:\local_repo\CTA_UI\start.py", line 31, in __init__
    self.param = paraTable()
  File "D:\local_repo\CTA_UI\UI_widget\paraTable.py", line 25, in __init__
    self.model.updateHeaderSize()
  File "D:\local_repo\CTA_UI\UI_widget\pandasModel.py", line 46, in updateHeaderSize
    sizeHint = self.sizeHintForIndex(index)
AttributeError: 'pandasModel' object has no attribute 'sizeHintForIndex'

2023-05-31 10:47:13
Traceback (most recent call last):
  File "D:\local_repo\CTA_UI\start.py", line 793, in <module>
    ex = Example()
  File "D:\local_repo\CTA_UI\start.py", line 31, in __init__
    self.param = paraTable()
  File "D:\local_repo\CTA_UI\UI_widget\paraTable.py", line 25, in __init__
    self.model.updateHeaderSize()
  File "D:\local_repo\CTA_UI\UI_widget\pandasModel.py", line 46, in updateHeaderSize
    sizeHint = self.sizeHintForIndex(index)
AttributeError: 'pandasModel' object has no attribute 'sizeHintForIndex'

2023-05-31 10:51:44
Traceback (most recent call last):
  File "D:\local_repo\CTA_UI\start.py", line 793, in <module>
    ex = Example()
  File "D:\local_repo\CTA_UI\start.py", line 31, in __init__
    self.param = paraTable()
  File "D:\local_repo\CTA_UI\UI_widget\paraTable.py", line 27, in __init__
    self.model.updateHeaderSize()
  File "D:\local_repo\CTA_UI\UI_widget\pandasModel.py", line 46, in updateHeaderSize
    sizeHint = self.sizeHintForIndex(index)
AttributeError: 'pandasModel' object has no attribute 'sizeHintForIndex'

2023-05-31 10:55:28
Traceback (most recent call last):
  File "D:\local_repo\CTA_UI\start.py", line 793, in <module>
    ex = Example()
  File "D:\local_repo\CTA_UI\start.py", line 31, in __init__
    self.param = paraTable()
  File "D:\local_repo\CTA_UI\UI_widget\paraTable.py", line 27, in __init__
    self.model.updateHeaderSize()
  File "D:\local_repo\CTA_UI\UI_widget\pandasModel.py", line 46, in updateHeaderSize
    sizeHint = self.sizeHintForIndex(index)
AttributeError: 'pandasModel' object has no attribute 'sizeHintForIndex'

2023-05-31 10:57:37
Traceback (most recent call last):
  File "D:\local_repo\CTA_UI\start.py", line 781, in <module>
    ex = Example()
  File "D:\local_repo\CTA_UI\start.py", line 32, in __init__
    self.param.model.updateHeaderSize()
  File "D:\local_repo\CTA_UI\UI_widget\pandasModel.py", line 46, in updateHeaderSize
    sizeHint = self.sizeHintForIndex(index)
AttributeError: 'pandasModel' object has no attribute 'sizeHintForIndex'

2023-05-31 11:04:26
Traceback (most recent call last):
  File "D:\local_repo\CTA_UI\start.py", line 781, in <module>
    ex = Example()
  File "D:\local_repo\CTA_UI\start.py", line 31, in __init__
    self.param = paraTable()
  File "D:\local_repo\CTA_UI\UI_widget\paraTable.py", line 25, in __init__
    self.model.updateHeaderSize()
  File "D:\local_repo\CTA_UI\UI_widget\pandasModel.py", line 46, in updateHeaderSize
    sizeHint = self.sizeHintForIndex(index)
AttributeError: 'pandasModel' object has no attribute 'sizeHintForIndex'

2023-05-31 11:05:38
Traceback (most recent call last):
  File "D:\local_repo\CTA_UI\start.py", line 781, in <module>
    ex = Example()
  File "D:\local_repo\CTA_UI\start.py", line 31, in __init__
    self.param = paraTable()
  File "D:\local_repo\CTA_UI\UI_widget\paraTable.py", line 25, in __init__
    self.model.updateHeaderSize()
  File "D:\local_repo\CTA_UI\UI_widget\pandasModel.py", line 147, in updateHeaderSize
    sizeHint = self.sizeHintForIndex(index)
AttributeError: 'pandasModel' object has no attribute 'sizeHintForIndex'

2023-05-31 11:06:56
Traceback (most recent call last):
  File "D:\local_repo\CTA_UI\start.py", line 781, in <module>
    ex = Example()
  File "D:\local_repo\CTA_UI\start.py", line 31, in __init__
    self.param = paraTable()
  File "D:\local_repo\CTA_UI\UI_widget\paraTable.py", line 24, in __init__
    self.view = TableView(self.model)
  File "D:\local_repo\CTA_UI\UI_widget\pandasModel.py", line 166, in __init__
    self.model.updateHeaderSize()
  File "D:\local_repo\CTA_UI\UI_widget\pandasModel.py", line 147, in updateHeaderSize
    sizeHint = self.sizeHintForIndex(index)
AttributeError: 'pandasModel' object has no attribute 'sizeHintForIndex'

2023-05-31 11:15:47
Traceback (most recent call last):
  File "D:\local_repo\CTA_UI\start.py", line 781, in <module>
    ex = Example()
  File "D:\local_repo\CTA_UI\start.py", line 31, in __init__
    self.param = paraTable()
  File "D:\local_repo\CTA_UI\UI_widget\paraTable.py", line 24, in __init__
    self.view = TableView(self.model)
  File "D:\local_repo\CTA_UI\UI_widget\pandasModel.py", line 149, in __init__
    self.updateHeaderSize()
  File "D:\local_repo\CTA_UI\UI_widget\pandasModel.py", line 153, in updateHeaderSize
    for row in range(self.rowCount()):
AttributeError: 'TableView' object has no attribute 'rowCount'

2023-05-31 11:18:13
Traceback (most recent call last):
  File "D:\local_repo\CTA_UI\start.py", line 781, in <module>
    ex = Example()
  File "D:\local_repo\CTA_UI\start.py", line 31, in __init__
    self.param = paraTable()
  File "D:\local_repo\CTA_UI\UI_widget\paraTable.py", line 24, in __init__
    self.view = TableView(self.model)
  File "D:\local_repo\CTA_UI\UI_widget\pandasModel.py", line 149, in __init__
    self.updateHeaderSize()
  File "D:\local_repo\CTA_UI\UI_widget\pandasModel.py", line 156, in updateHeaderSize
    sizeHint = self.model.sizeHint(index, Qt.SizeHintRole)
AttributeError: 'pandasModel' object has no attribute 'sizeHint'

2023-05-31 11:26:33
Traceback (most recent call last):
  File "D:\local_repo\CTA_UI\start.py", line 781, in <module>
    ex = Example()
  File "D:\local_repo\CTA_UI\start.py", line 31, in __init__
    self.param = paraTable()
  File "D:\local_repo\CTA_UI\UI_widget\paraTable.py", line 24, in __init__
    self.view = TableView(self.model)
  File "D:\local_repo\CTA_UI\UI_widget\pandasModel.py", line 149, in __init__
    self.updateHeaderSize()
  File "D:\local_repo\CTA_UI\UI_widget\pandasModel.py", line 156, in updateHeaderSize
    sizeHint = self.model.sizeHint(index, Qt.SizeHintRole)
AttributeError: 'pandasModel' object has no attribute 'sizeHint'

2023-05-31 11:28:57
Traceback (most recent call last):
  File "D:\local_repo\CTA_UI\start.py", line 781, in <module>
    ex = Example()
  File "D:\local_repo\CTA_UI\start.py", line 32, in __init__
    self.param.model.updateHeaderSize()
AttributeError: 'pandasModel' object has no attribute 'updateHeaderSize'

2023-05-31 13:52:29
Traceback (most recent call last):
  File "D:\local_repo\CTA_UI\start.py", line 780, in <module>
    ex = Example()
  File "D:\local_repo\CTA_UI\start.py", line 31, in __init__
    self.param = paraTable()
  File "D:\local_repo\CTA_UI\UI_widget\paraTable.py", line 24, in __init__
    self.view = TableView(self.model)
  File "D:\local_repo\CTA_UI\UI_widget\pandasModel.py", line 154, in __init__
    self.updateHeaderSize()
  File "D:\local_repo\CTA_UI\UI_widget\pandasModel.py", line 167, in updateHeaderSize
    self.horizontalHeader().resizeSection(col, sizeHint.width() * 0.5 + len(text) * 8)
TypeError: resizeSection(self, int, int): argument 2 has unexpected type 'float'

2023-05-31 14:31:01
Traceback (most recent call last):
  File "D:\local_repo\CTA_UI\start.py", line 780, in <module>
    ex = Example()
  File "D:\local_repo\CTA_UI\start.py", line 31, in __init__
    self.param = paraTable()
  File "D:\local_repo\CTA_UI\UI_widget\paraTable.py", line 19, in __init__
    info_df = info_df.apply(lambda x: int(x) if x == int(x) else x)
  File "C:\Users\Han.Hao\AppData\Local\anaconda3\lib\site-packages\pandas\core\frame.py", line 9568, in apply
    return op.apply().__finalize__(self, method="apply")
  File "C:\Users\Han.Hao\AppData\Local\anaconda3\lib\site-packages\pandas\core\apply.py", line 764, in apply
    return self.apply_standard()
  File "C:\Users\Han.Hao\AppData\Local\anaconda3\lib\site-packages\pandas\core\apply.py", line 891, in apply_standard
    results, res_index = self.apply_series_generator()
  File "C:\Users\Han.Hao\AppData\Local\anaconda3\lib\site-packages\pandas\core\apply.py", line 907, in apply_series_generator
    results[i] = self.f(v)
  File "D:\local_repo\CTA_UI\UI_widget\paraTable.py", line 19, in <lambda>
    info_df = info_df.apply(lambda x: int(x) if x == int(x) else x)
  File "C:\Users\Han.Hao\AppData\Local\anaconda3\lib\site-packages\pandas\core\series.py", line 206, in wrapper
    raise TypeError(f"cannot convert the series to {converter}")
TypeError: cannot convert the series to <class 'int'>

2023-05-31 14:31:12
Traceback (most recent call last):
  File "D:\local_repo\CTA_UI\start.py", line 780, in <module>
    ex = Example()
  File "D:\local_repo\CTA_UI\start.py", line 31, in __init__
    self.param = paraTable()
  File "D:\local_repo\CTA_UI\UI_widget\paraTable.py", line 19, in __init__
    info_df = info_df.apply(lambda x: int(x) if x == int(x) else x)
  File "C:\Users\Han.Hao\AppData\Local\anaconda3\lib\site-packages\pandas\core\frame.py", line 9568, in apply
    return op.apply().__finalize__(self, method="apply")
  File "C:\Users\Han.Hao\AppData\Local\anaconda3\lib\site-packages\pandas\core\apply.py", line 764, in apply
    return self.apply_standard()
  File "C:\Users\Han.Hao\AppData\Local\anaconda3\lib\site-packages\pandas\core\apply.py", line 891, in apply_standard
    results, res_index = self.apply_series_generator()
  File "C:\Users\Han.Hao\AppData\Local\anaconda3\lib\site-packages\pandas\core\apply.py", line 907, in apply_series_generator
    results[i] = self.f(v)
  File "D:\local_repo\CTA_UI\UI_widget\paraTable.py", line 19, in <lambda>
    info_df = info_df.apply(lambda x: int(x) if x == int(x) else x)
  File "C:\Users\Han.Hao\AppData\Local\anaconda3\lib\site-packages\pandas\core\series.py", line 206, in wrapper
    raise TypeError(f"cannot convert the series to {converter}")
TypeError: cannot convert the series to <class 'int'>

2023-05-31 14:32:52
Traceback (most recent call last):
  File "D:\local_repo\CTA_UI\start.py", line 780, in <module>
    ex = Example()
  File "D:\local_repo\CTA_UI\start.py", line 31, in __init__
    self.param = paraTable()
  File "D:\local_repo\CTA_UI\UI_widget\paraTable.py", line 23, in __init__
    self.model = pandasModel(info_df)
  File "D:\local_repo\CTA_UI\UI_widget\pandasModel.py", line 31, in __init__
    self._data = self._data.apply(lambda x: x.apply(lambda y: int(y) if y == int(y) else y))
  File "C:\Users\Han.Hao\AppData\Local\anaconda3\lib\site-packages\pandas\core\frame.py", line 9568, in apply
    return op.apply().__finalize__(self, method="apply")
  File "C:\Users\Han.Hao\AppData\Local\anaconda3\lib\site-packages\pandas\core\apply.py", line 764, in apply
    return self.apply_standard()
  File "C:\Users\Han.Hao\AppData\Local\anaconda3\lib\site-packages\pandas\core\apply.py", line 891, in apply_standard
    results, res_index = self.apply_series_generator()
  File "C:\Users\Han.Hao\AppData\Local\anaconda3\lib\site-packages\pandas\core\apply.py", line 907, in apply_series_generator
    results[i] = self.f(v)
  File "D:\local_repo\CTA_UI\UI_widget\pandasModel.py", line 31, in <lambda>
    self._data = self._data.apply(lambda x: x.apply(lambda y: int(y) if y == int(y) else y))
  File "C:\Users\Han.Hao\AppData\Local\anaconda3\lib\site-packages\pandas\core\series.py", line 4771, in apply
    return SeriesApply(self, func, convert_dtype, args, kwargs).apply()
  File "C:\Users\Han.Hao\AppData\Local\anaconda3\lib\site-packages\pandas\core\apply.py", line 1123, in apply
    return self.apply_standard()
  File "C:\Users\Han.Hao\AppData\Local\anaconda3\lib\site-packages\pandas\core\apply.py", line 1174, in apply_standard
    mapped = lib.map_infer(
  File "pandas\_libs\lib.pyx", line 2924, in pandas._libs.lib.map_infer
  File "D:\local_repo\CTA_UI\UI_widget\pandasModel.py", line 31, in <lambda>
    self._data = self._data.apply(lambda x: x.apply(lambda y: int(y) if y == int(y) else y))
ValueError: invalid literal for int() with base 10: 'Z:\\300_Group\\HFT\\Program\\CTA_UI\\barplot\\20230531\\20230531-A2307-2309.png'

2023-05-31 14:33:57
Traceback (most recent call last):
  File "D:\local_repo\CTA_UI\start.py", line 780, in <module>
    ex = Example()
  File "D:\local_repo\CTA_UI\start.py", line 31, in __init__
    self.param = paraTable()
  File "D:\local_repo\CTA_UI\UI_widget\paraTable.py", line 23, in __init__
    self.model = pandasModel(info_df)
  File "D:\local_repo\CTA_UI\UI_widget\pandasModel.py", line 31, in __init__
    self._data = self._data.apply(lambda x: x.apply(lambda y: int(y) if y == int(y) else y) if x.dtype == float else x)
  File "C:\Users\Han.Hao\AppData\Local\anaconda3\lib\site-packages\pandas\core\frame.py", line 9568, in apply
    return op.apply().__finalize__(self, method="apply")
  File "C:\Users\Han.Hao\AppData\Local\anaconda3\lib\site-packages\pandas\core\apply.py", line 764, in apply
    return self.apply_standard()
  File "C:\Users\Han.Hao\AppData\Local\anaconda3\lib\site-packages\pandas\core\apply.py", line 891, in apply_standard
    results, res_index = self.apply_series_generator()
  File "C:\Users\Han.Hao\AppData\Local\anaconda3\lib\site-packages\pandas\core\apply.py", line 907, in apply_series_generator
    results[i] = self.f(v)
  File "D:\local_repo\CTA_UI\UI_widget\pandasModel.py", line 31, in <lambda>
    self._data = self._data.apply(lambda x: x.apply(lambda y: int(y) if y == int(y) else y) if x.dtype == float else x)
  File "C:\Users\Han.Hao\AppData\Local\anaconda3\lib\site-packages\pandas\core\series.py", line 4771, in apply
    return SeriesApply(self, func, convert_dtype, args, kwargs).apply()
  File "C:\Users\Han.Hao\AppData\Local\anaconda3\lib\site-packages\pandas\core\apply.py", line 1123, in apply
    return self.apply_standard()
  File "C:\Users\Han.Hao\AppData\Local\anaconda3\lib\site-packages\pandas\core\apply.py", line 1174, in apply_standard
    mapped = lib.map_infer(
  File "pandas\_libs\lib.pyx", line 2924, in pandas._libs.lib.map_infer
  File "D:\local_repo\CTA_UI\UI_widget\pandasModel.py", line 31, in <lambda>
    self._data = self._data.apply(lambda x: x.apply(lambda y: int(y) if y == int(y) else y) if x.dtype == float else x)
ValueError: cannot convert float NaN to integer

2023-05-31 14:35:06
Traceback (most recent call last):
  File "D:\local_repo\CTA_UI\start.py", line 780, in <module>
    ex = Example()
  File "D:\local_repo\CTA_UI\start.py", line 31, in __init__
    self.param = paraTable()
  File "D:\local_repo\CTA_UI\UI_widget\paraTable.py", line 23, in __init__
    self.model = pandasModel(info_df)
  File "D:\local_repo\CTA_UI\UI_widget\pandasModel.py", line 31, in __init__
    self._data = self._data.apply(lambda x: x.apply(lambda y: int(y) if y == int(y) else y) if x.dtype == float else x)
  File "C:\Users\Han.Hao\AppData\Local\anaconda3\lib\site-packages\pandas\core\frame.py", line 9568, in apply
    return op.apply().__finalize__(self, method="apply")
  File "C:\Users\Han.Hao\AppData\Local\anaconda3\lib\site-packages\pandas\core\apply.py", line 764, in apply
    return self.apply_standard()
  File "C:\Users\Han.Hao\AppData\Local\anaconda3\lib\site-packages\pandas\core\apply.py", line 891, in apply_standard
    results, res_index = self.apply_series_generator()
  File "C:\Users\Han.Hao\AppData\Local\anaconda3\lib\site-packages\pandas\core\apply.py", line 907, in apply_series_generator
    results[i] = self.f(v)
  File "D:\local_repo\CTA_UI\UI_widget\pandasModel.py", line 31, in <lambda>
    self._data = self._data.apply(lambda x: x.apply(lambda y: int(y) if y == int(y) else y) if x.dtype == float else x)
  File "C:\Users\Han.Hao\AppData\Local\anaconda3\lib\site-packages\pandas\core\series.py", line 4771, in apply
    return SeriesApply(self, func, convert_dtype, args, kwargs).apply()
  File "C:\Users\Han.Hao\AppData\Local\anaconda3\lib\site-packages\pandas\core\apply.py", line 1123, in apply
    return self.apply_standard()
  File "C:\Users\Han.Hao\AppData\Local\anaconda3\lib\site-packages\pandas\core\apply.py", line 1174, in apply_standard
    mapped = lib.map_infer(
  File "pandas\_libs\lib.pyx", line 2924, in pandas._libs.lib.map_infer
  File "D:\local_repo\CTA_UI\UI_widget\pandasModel.py", line 31, in <lambda>
    self._data = self._data.apply(lambda x: x.apply(lambda y: int(y) if y == int(y) else y) if x.dtype == float else x)
ValueError: cannot convert float NaN to integer

2023-05-31 14:35:38
Traceback (most recent call last):
  File "D:\local_repo\CTA_UI\start.py", line 780, in <module>
    ex = Example()
  File "D:\local_repo\CTA_UI\start.py", line 31, in __init__
    self.param = paraTable()
  File "D:\local_repo\CTA_UI\UI_widget\paraTable.py", line 23, in __init__
    self.model = pandasModel(info_df)
  File "D:\local_repo\CTA_UI\UI_widget\pandasModel.py", line 32, in __init__
    self._data = self._data.apply(lambda x: x.apply(lambda y: int(y) if y == int(y) else y) if x.dtype == float else x)
  File "C:\Users\Han.Hao\AppData\Local\anaconda3\lib\site-packages\pandas\core\frame.py", line 9568, in apply
    return op.apply().__finalize__(self, method="apply")
  File "C:\Users\Han.Hao\AppData\Local\anaconda3\lib\site-packages\pandas\core\apply.py", line 764, in apply
    return self.apply_standard()
  File "C:\Users\Han.Hao\AppData\Local\anaconda3\lib\site-packages\pandas\core\apply.py", line 891, in apply_standard
    results, res_index = self.apply_series_generator()
  File "C:\Users\Han.Hao\AppData\Local\anaconda3\lib\site-packages\pandas\core\apply.py", line 907, in apply_series_generator
    results[i] = self.f(v)
  File "D:\local_repo\CTA_UI\UI_widget\pandasModel.py", line 32, in <lambda>
    self._data = self._data.apply(lambda x: x.apply(lambda y: int(y) if y == int(y) else y) if x.dtype == float else x)
  File "C:\Users\Han.Hao\AppData\Local\anaconda3\lib\site-packages\pandas\core\series.py", line 4771, in apply
    return SeriesApply(self, func, convert_dtype, args, kwargs).apply()
  File "C:\Users\Han.Hao\AppData\Local\anaconda3\lib\site-packages\pandas\core\apply.py", line 1123, in apply
    return self.apply_standard()
  File "C:\Users\Han.Hao\AppData\Local\anaconda3\lib\site-packages\pandas\core\apply.py", line 1174, in apply_standard
    mapped = lib.map_infer(
  File "pandas\_libs\lib.pyx", line 2924, in pandas._libs.lib.map_infer
  File "D:\local_repo\CTA_UI\UI_widget\pandasModel.py", line 32, in <lambda>
    self._data = self._data.apply(lambda x: x.apply(lambda y: int(y) if y == int(y) else y) if x.dtype == float else x)
ValueError: cannot convert float NaN to integer

2023-06-19 14:34:56
Traceback (most recent call last):
  File "D:\local_repo\CTA_UI\start.py", line 825, in <module>
    ex = Arbitrator()
  File "D:\local_repo\CTA_UI\start.py", line 43, in __init__
    self.initUI()
  File "D:\local_repo\CTA_UI\start.py", line 116, in initUI
    self.editMenu.addAction(undoAct)
NameError: name 'undoAct' is not defined

2023-06-19 14:43:50
Traceback (most recent call last):
  File "D:\local_repo\CTA_UI\start.py", line 829, in <module>
    ex = Arbitrator()
  File "D:\local_repo\CTA_UI\start.py", line 37, in __init__
    self.param = paraTable()
  File "D:\local_repo\CTA_UI\UI_widget\paraTable.py", line 20, in __init__
    self.model = pandasModel(info_df)
  File "D:\local_repo\CTA_UI\UI_widget\pandasModel.py", line 29, in __init__
    self._data = self.addColumnToDf(data, barplot_flag, checkbox_flag)
  File "D:\local_repo\CTA_UI\UI_widget\pandasModel.py", line 141, in addColumnToDf
    data.insert(0, 'BarPlot', data.apply(lambda x: pairname_to_plotdir(x.name), axis=1))
  File "C:\Users\Han.Hao\AppData\Local\anaconda3\lib\site-packages\pandas\core\frame.py", line 4817, in insert
    raise ValueError(f"cannot insert {column}, already exists")
ValueError: cannot insert BarPlot, already exists

2023-06-19 14:44:14
Traceback (most recent call last):
  File "D:\local_repo\CTA_UI\start.py", line 829, in <module>
    ex = Arbitrator()
  File "D:\local_repo\CTA_UI\start.py", line 37, in __init__
    self.param = paraTable()
  File "D:\local_repo\CTA_UI\UI_widget\paraTable.py", line 20, in __init__
    self.model = pandasModel(info_df)
  File "D:\local_repo\CTA_UI\UI_widget\pandasModel.py", line 29, in __init__
    self._data = self.addColumnToDf(data, barplot_flag, checkbox_flag)
  File "D:\local_repo\CTA_UI\UI_widget\pandasModel.py", line 141, in addColumnToDf
    data.insert(0, 'BarPlot', data.apply(lambda x: pairname_to_plotdir(x.name), axis=1))
  File "C:\Users\Han.Hao\AppData\Local\anaconda3\lib\site-packages\pandas\core\frame.py", line 4817, in insert
    raise ValueError(f"cannot insert {column}, already exists")
ValueError: cannot insert BarPlot, already exists

2023-06-19 14:44:44
Traceback (most recent call last):
  File "D:\local_repo\CTA_UI\start.py", line 829, in <module>
    ex = Arbitrator()
  File "D:\local_repo\CTA_UI\start.py", line 37, in __init__
    self.param = paraTable()
  File "D:\local_repo\CTA_UI\UI_widget\paraTable.py", line 20, in __init__
    self.model = pandasModel(info_df)
  File "D:\local_repo\CTA_UI\UI_widget\pandasModel.py", line 29, in __init__
    self._data = self.addColumnToDf(data, barplot_flag, checkbox_flag)
  File "D:\local_repo\CTA_UI\UI_widget\pandasModel.py", line 141, in addColumnToDf
    data.insert(0, 'BarPlot', data.apply(lambda x: pairname_to_plotdir(x.name), axis=1))
  File "C:\Users\Han.Hao\AppData\Local\anaconda3\lib\site-packages\pandas\core\frame.py", line 4817, in insert
    raise ValueError(f"cannot insert {column}, already exists")
ValueError: cannot insert BarPlot, already exists

2023-06-20 15:34:42
Traceback (most recent call last):
  File "D:\local_repo\CTA_UI\start.py", line 831, in <module>
    ex = Arbitrator()
  File "D:\local_repo\CTA_UI\start.py", line 40, in __init__
    self.initUI()
  File "D:\local_repo\CTA_UI\start.py", line 251, in initUI
    btn_check.clicked.connect(self.check_param_pairs)
AttributeError: 'Arbitrator' object has no attribute 'check_param_pairs'

2023-07-18 08:45:38
Traceback (most recent call last):
  File "D:\local_repo\CTA_UI\start.py", line 438, in upload_param
    flink.pull_from_UI_to_market(config)
  File "D:\local_repo\CTA_UI\utils\flink.py", line 54, in pull_from_UI_to_market
    ssh.connect()
  File "D:\local_repo\CTA_UI\utils\sftp.py", line 18, in connect
    transport = paramiko.Transport((self.host,self.port))
  File "C:\Users\Han.Hao\AppData\Local\anaconda3\lib\site-packages\paramiko\transport.py", line 415, in __init__
    raise SSHException(
paramiko.ssh_exception.SSHException: Unable to connect to 39.97.106.35: [WinError 10061] 由于目标计算机积极拒绝，无法连接。

2023-07-18 08:45:41
Traceback (most recent call last):
  File "D:\local_repo\CTA_UI\start.py", line 438, in upload_param
    flink.pull_from_UI_to_market(config)
  File "D:\local_repo\CTA_UI\utils\flink.py", line 54, in pull_from_UI_to_market
    ssh.connect()
  File "D:\local_repo\CTA_UI\utils\sftp.py", line 18, in connect
    transport = paramiko.Transport((self.host,self.port))
  File "C:\Users\Han.Hao\AppData\Local\anaconda3\lib\site-packages\paramiko\transport.py", line 415, in __init__
    raise SSHException(
paramiko.ssh_exception.SSHException: Unable to connect to 39.97.106.35: [WinError 10061] 由于目标计算机积极拒绝，无法连接。

2023-07-18 10:15:46
Traceback (most recent call last):
  File "D:\local_repo\CTA_UI\start.py", line 441, in upload_param
    flink.pull_from_UI_to_market(config)
  File "D:\local_repo\CTA_UI\utils\flink.py", line 54, in pull_from_UI_to_market
    ssh.connect()
  File "D:\local_repo\CTA_UI\utils\sftp.py", line 18, in connect
    transport = paramiko.Transport((self.host,self.port))
  File "C:\Users\Han.Hao\AppData\Local\anaconda3\lib\site-packages\paramiko\transport.py", line 415, in __init__
    raise SSHException(
paramiko.ssh_exception.SSHException: Unable to connect to 39.97.106.35: [WinError 10061] 由于目标计算机积极拒绝，无法连接。

2023-07-18 14:07:12
Traceback (most recent call last):
  File "D:\local_repo\CTA_UI\start.py", line 441, in upload_param
    flink.pull_from_UI_to_market(config)
  File "D:\local_repo\CTA_UI\utils\flink.py", line 54, in pull_from_UI_to_market
    ssh.connect()
  File "D:\local_repo\CTA_UI\utils\sftp.py", line 18, in connect
    transport = paramiko.Transport((self.host,self.port))
  File "C:\Users\Han.Hao\AppData\Local\anaconda3\lib\site-packages\paramiko\transport.py", line 415, in __init__
    raise SSHException(
paramiko.ssh_exception.SSHException: Unable to connect to 39.97.106.35: [WinError 10061] 由于目标计算机积极拒绝，无法连接。

2023-07-18 14:07:27
Traceback (most recent call last):
  File "D:\local_repo\CTA_UI\start.py", line 441, in upload_param
    flink.pull_from_UI_to_market(config)
  File "D:\local_repo\CTA_UI\utils\flink.py", line 54, in pull_from_UI_to_market
    ssh.connect()
  File "D:\local_repo\CTA_UI\utils\sftp.py", line 18, in connect
    transport = paramiko.Transport((self.host,self.port))
  File "C:\Users\Han.Hao\AppData\Local\anaconda3\lib\site-packages\paramiko\transport.py", line 415, in __init__
    raise SSHException(
paramiko.ssh_exception.SSHException: Unable to connect to 39.97.106.35: [WinError 10061] 由于目标计算机积极拒绝，无法连接。

2023-07-18 17:20:14
Traceback (most recent call last):
  File "D:\local_repo\CTA_UI\start.py", line 431, in upload_param
    flink.pull_from_UI_to_cloud(config)
  File "D:\local_repo\CTA_UI\utils\flink.py", line 36, in pull_from_UI_to_cloud
    ssh.upload(param_dir, windows_to_linux(os.path.join(dest_acc_dir, "params.csv")))
  File "D:\local_repo\CTA_UI\utils\sftp.py", line 30, in upload
    sftp.put(local_path, target_path)
  File "C:\Users\Han.Hao\AppData\Local\anaconda3\lib\site-packages\paramiko\sftp_client.py", line 757, in put
    file_size = os.stat(localpath).st_size
FileNotFoundError: [WinError 3] 系统找不到指定的路径。: 'D:\\local_repo\\CTA_UI\\params\\cta_lqqq_zx\\params.csv'

2023-07-18 17:20:22
Traceback (most recent call last):
  File "D:\local_repo\CTA_UI\start.py", line 441, in upload_param
    flink.pull_from_UI_to_market(config)
  File "D:\local_repo\CTA_UI\utils\flink.py", line 54, in pull_from_UI_to_market
    ssh.connect()
  File "D:\local_repo\CTA_UI\utils\sftp.py", line 18, in connect
    transport = paramiko.Transport((self.host,self.port))
  File "C:\Users\Han.Hao\AppData\Local\anaconda3\lib\site-packages\paramiko\transport.py", line 415, in __init__
    raise SSHException(
paramiko.ssh_exception.SSHException: Unable to connect to 39.97.106.35: [WinError 10061] 由于目标计算机积极拒绝，无法连接。

2023-07-18 17:22:12
Traceback (most recent call last):
  File "D:\local_repo\CTA_UI\start.py", line 441, in upload_param
    flink.pull_from_UI_to_market(config)
  File "D:\local_repo\CTA_UI\utils\flink.py", line 54, in pull_from_UI_to_market
    ssh.connect()
  File "D:\local_repo\CTA_UI\utils\sftp.py", line 18, in connect
    transport = paramiko.Transport((self.host,self.port))
  File "C:\Users\Han.Hao\AppData\Local\anaconda3\lib\site-packages\paramiko\transport.py", line 415, in __init__
    raise SSHException(
paramiko.ssh_exception.SSHException: Unable to connect to 39.97.106.35: [WinError 10061] 由于目标计算机积极拒绝，无法连接。

2023-07-19 15:37:24
Traceback (most recent call last):
  File "D:\local_repo\CTA_UI\start.py", line 441, in upload_param
    flink.pull_from_UI_to_market(config)
  File "D:\local_repo\CTA_UI\utils\flink.py", line 54, in pull_from_UI_to_market
    ssh.connect()
  File "D:\local_repo\CTA_UI\utils\sftp.py", line 18, in connect
    transport = paramiko.Transport((self.host,self.port))
  File "C:\Users\Han.Hao\AppData\Local\anaconda3\lib\site-packages\paramiko\transport.py", line 415, in __init__
    raise SSHException(
paramiko.ssh_exception.SSHException: Unable to connect to 39.97.106.35: [WinError 10061] 由于目标计算机积极拒绝，无法连接。

2023-07-19 15:43:17
Traceback (most recent call last):
  File "D:\local_repo\CTA_UI\start.py", line 441, in upload_param
    flink.pull_from_UI_to_market(config)
  File "D:\local_repo\CTA_UI\utils\flink.py", line 54, in pull_from_UI_to_market
    ssh.connect()
  File "D:\local_repo\CTA_UI\utils\sftp.py", line 18, in connect
    transport = paramiko.Transport((self.host,self.port))
  File "C:\Users\Han.Hao\AppData\Local\anaconda3\lib\site-packages\paramiko\transport.py", line 415, in __init__
    raise SSHException(
paramiko.ssh_exception.SSHException: Unable to connect to 39.97.106.35: [WinError 10061] 由于目标计算机积极拒绝，无法连接。

2023-07-19 15:43:23
Traceback (most recent call last):
  File "D:\local_repo\CTA_UI\start.py", line 441, in upload_param
    flink.pull_from_UI_to_market(config)
  File "D:\local_repo\CTA_UI\utils\flink.py", line 54, in pull_from_UI_to_market
    ssh.connect()
  File "D:\local_repo\CTA_UI\utils\sftp.py", line 18, in connect
    transport = paramiko.Transport((self.host,self.port))
  File "C:\Users\Han.Hao\AppData\Local\anaconda3\lib\site-packages\paramiko\transport.py", line 415, in __init__
    raise SSHException(
paramiko.ssh_exception.SSHException: Unable to connect to 39.97.106.35: [WinError 10061] 由于目标计算机积极拒绝，无法连接。

2023-07-19 16:11:58
Traceback (most recent call last):
  File "D:\local_repo\CTA_UI\start.py", line 441, in upload_param
    flink.pull_from_UI_to_market(config)
  File "D:\local_repo\CTA_UI\utils\flink.py", line 54, in pull_from_UI_to_market
    ssh.connect()
  File "D:\local_repo\CTA_UI\utils\sftp.py", line 18, in connect
    transport = paramiko.Transport((self.host,self.port))
  File "C:\Users\Han.Hao\AppData\Local\anaconda3\lib\site-packages\paramiko\transport.py", line 415, in __init__
    raise SSHException(
paramiko.ssh_exception.SSHException: Unable to connect to 39.97.106.35: [WinError 10061] 由于目标计算机积极拒绝，无法连接。

2023-07-19 16:12:03
Traceback (most recent call last):
  File "D:\local_repo\CTA_UI\start.py", line 441, in upload_param
    flink.pull_from_UI_to_market(config)
  File "D:\local_repo\CTA_UI\utils\flink.py", line 54, in pull_from_UI_to_market
    ssh.connect()
  File "D:\local_repo\CTA_UI\utils\sftp.py", line 18, in connect
    transport = paramiko.Transport((self.host,self.port))
  File "C:\Users\Han.Hao\AppData\Local\anaconda3\lib\site-packages\paramiko\transport.py", line 415, in __init__
    raise SSHException(
paramiko.ssh_exception.SSHException: Unable to connect to 39.97.106.35: [WinError 10061] 由于目标计算机积极拒绝，无法连接。

2023-07-19 16:12:10
Traceback (most recent call last):
  File "D:\local_repo\CTA_UI\start.py", line 441, in upload_param
    flink.pull_from_UI_to_market(config)
  File "D:\local_repo\CTA_UI\utils\flink.py", line 54, in pull_from_UI_to_market
    ssh.connect()
  File "D:\local_repo\CTA_UI\utils\sftp.py", line 18, in connect
    transport = paramiko.Transport((self.host,self.port))
  File "C:\Users\Han.Hao\AppData\Local\anaconda3\lib\site-packages\paramiko\transport.py", line 415, in __init__
    raise SSHException(
paramiko.ssh_exception.SSHException: Unable to connect to 39.97.106.35: [WinError 10061] 由于目标计算机积极拒绝，无法连接。

2023-07-19 16:13:46
Traceback (most recent call last):
  File "D:\local_repo\CTA_UI\start.py", line 441, in upload_param
    flink.pull_from_UI_to_market(config)
  File "D:\local_repo\CTA_UI\utils\flink.py", line 54, in pull_from_UI_to_market
    ssh.connect()
  File "D:\local_repo\CTA_UI\utils\sftp.py", line 18, in connect
    transport = paramiko.Transport((self.host,self.port))
  File "C:\Users\Han.Hao\AppData\Local\anaconda3\lib\site-packages\paramiko\transport.py", line 415, in __init__
    raise SSHException(
paramiko.ssh_exception.SSHException: Unable to connect to 39.97.106.35: [WinError 10061] 由于目标计算机积极拒绝，无法连接。

2023-07-19 16:13:51
Traceback (most recent call last):
  File "D:\local_repo\CTA_UI\start.py", line 441, in upload_param
    flink.pull_from_UI_to_market(config)
  File "D:\local_repo\CTA_UI\utils\flink.py", line 54, in pull_from_UI_to_market
    ssh.connect()
  File "D:\local_repo\CTA_UI\utils\sftp.py", line 18, in connect
    transport = paramiko.Transport((self.host,self.port))
  File "C:\Users\Han.Hao\AppData\Local\anaconda3\lib\site-packages\paramiko\transport.py", line 415, in __init__
    raise SSHException(
paramiko.ssh_exception.SSHException: Unable to connect to 39.97.106.35: [WinError 10061] 由于目标计算机积极拒绝，无法连接。

2023-07-19 16:16:56
Traceback (most recent call last):
  File "D:\local_repo\CTA_UI\start.py", line 441, in upload_param
    flink.pull_from_UI_to_market(config)
  File "D:\local_repo\CTA_UI\utils\flink.py", line 54, in pull_from_UI_to_market
    ssh.connect()
  File "D:\local_repo\CTA_UI\utils\sftp.py", line 18, in connect
    transport = paramiko.Transport((self.host,self.port))
  File "C:\Users\Han.Hao\AppData\Local\anaconda3\lib\site-packages\paramiko\transport.py", line 415, in __init__
    raise SSHException(
paramiko.ssh_exception.SSHException: Unable to connect to 39.97.106.35: [WinError 10061] 由于目标计算机积极拒绝，无法连接。

2023-07-19 16:17:04
Traceback (most recent call last):
  File "D:\local_repo\CTA_UI\start.py", line 441, in upload_param
    flink.pull_from_UI_to_market(config)
  File "D:\local_repo\CTA_UI\utils\flink.py", line 54, in pull_from_UI_to_market
    ssh.connect()
  File "D:\local_repo\CTA_UI\utils\sftp.py", line 18, in connect
    transport = paramiko.Transport((self.host,self.port))
  File "C:\Users\Han.Hao\AppData\Local\anaconda3\lib\site-packages\paramiko\transport.py", line 415, in __init__
    raise SSHException(
paramiko.ssh_exception.SSHException: Unable to connect to 39.97.106.35: [WinError 10061] 由于目标计算机积极拒绝，无法连接。

2023-07-19 16:17:10
Traceback (most recent call last):
  File "D:\local_repo\CTA_UI\start.py", line 441, in upload_param
    flink.pull_from_UI_to_market(config)
  File "D:\local_repo\CTA_UI\utils\flink.py", line 54, in pull_from_UI_to_market
    ssh.connect()
  File "D:\local_repo\CTA_UI\utils\sftp.py", line 18, in connect
    transport = paramiko.Transport((self.host,self.port))
  File "C:\Users\Han.Hao\AppData\Local\anaconda3\lib\site-packages\paramiko\transport.py", line 415, in __init__
    raise SSHException(
paramiko.ssh_exception.SSHException: Unable to connect to 39.97.106.35: [WinError 10061] 由于目标计算机积极拒绝，无法连接。

2023-07-19 16:17:15
Traceback (most recent call last):
  File "D:\local_repo\CTA_UI\start.py", line 441, in upload_param
    flink.pull_from_UI_to_market(config)
  File "D:\local_repo\CTA_UI\utils\flink.py", line 54, in pull_from_UI_to_market
    ssh.connect()
  File "D:\local_repo\CTA_UI\utils\sftp.py", line 18, in connect
    transport = paramiko.Transport((self.host,self.port))
  File "C:\Users\Han.Hao\AppData\Local\anaconda3\lib\site-packages\paramiko\transport.py", line 415, in __init__
    raise SSHException(
paramiko.ssh_exception.SSHException: Unable to connect to 39.97.106.35: [WinError 10061] 由于目标计算机积极拒绝，无法连接。

2023-07-19 16:20:49
Traceback (most recent call last):
  File "D:\local_repo\CTA_UI\start.py", line 441, in upload_param
    try:
  File "D:\local_repo\CTA_UI\utils\flink.py", line 54, in pull_from_UI_to_market
    ssh.connect()
  File "D:\local_repo\CTA_UI\utils\sftp.py", line 18, in connect
    transport = paramiko.Transport((self.host,self.port))
  File "C:\Users\Han.Hao\AppData\Local\anaconda3\lib\site-packages\paramiko\transport.py", line 415, in __init__
    raise SSHException(
paramiko.ssh_exception.SSHException: Unable to connect to 39.97.106.35: [WinError 10061] 由于目标计算机积极拒绝，无法连接。

2023-07-19 16:20:54
Traceback (most recent call last):
  File "D:\local_repo\CTA_UI\start.py", line 441, in upload_param
    try:
  File "D:\local_repo\CTA_UI\utils\flink.py", line 54, in pull_from_UI_to_market
    ssh.connect()
  File "D:\local_repo\CTA_UI\utils\sftp.py", line 18, in connect
    transport = paramiko.Transport((self.host,self.port))
  File "C:\Users\Han.Hao\AppData\Local\anaconda3\lib\site-packages\paramiko\transport.py", line 415, in __init__
    raise SSHException(
paramiko.ssh_exception.SSHException: Unable to connect to 39.97.106.35: [WinError 10061] 由于目标计算机积极拒绝，无法连接。

2023-07-19 16:21:00
Traceback (most recent call last):
  File "D:\local_repo\CTA_UI\start.py", line 441, in upload_param
    try:
  File "D:\local_repo\CTA_UI\utils\flink.py", line 54, in pull_from_UI_to_market
    ssh.connect()
  File "D:\local_repo\CTA_UI\utils\sftp.py", line 18, in connect
    transport = paramiko.Transport((self.host,self.port))
  File "C:\Users\Han.Hao\AppData\Local\anaconda3\lib\site-packages\paramiko\transport.py", line 415, in __init__
    raise SSHException(
paramiko.ssh_exception.SSHException: Unable to connect to 39.97.106.35: [WinError 10061] 由于目标计算机积极拒绝，无法连接。

2023-07-19 16:25:50
Traceback (most recent call last):
  File "D:\local_repo\CTA_UI\start.py", line 441, in upload_param
    try:
  File "D:\local_repo\CTA_UI\utils\flink.py", line 54, in pull_from_UI_to_market
    ssh.connect()
  File "D:\local_repo\CTA_UI\utils\sftp.py", line 18, in connect
    transport = paramiko.Transport((self.host,self.port))
  File "C:\Users\Han.Hao\AppData\Local\anaconda3\lib\site-packages\paramiko\transport.py", line 415, in __init__
    raise SSHException(
paramiko.ssh_exception.SSHException: Unable to connect to 39.97.106.35: [WinError 10061] 由于目标计算机积极拒绝，无法连接。

2023-07-19 16:25:56
Traceback (most recent call last):
  File "D:\local_repo\CTA_UI\start.py", line 441, in upload_param
    try:
  File "D:\local_repo\CTA_UI\utils\flink.py", line 54, in pull_from_UI_to_market
    ssh.connect()
  File "D:\local_repo\CTA_UI\utils\sftp.py", line 18, in connect
    transport = paramiko.Transport((self.host,self.port))
  File "C:\Users\Han.Hao\AppData\Local\anaconda3\lib\site-packages\paramiko\transport.py", line 415, in __init__
    raise SSHException(
paramiko.ssh_exception.SSHException: Unable to connect to 39.97.106.35: [WinError 10061] 由于目标计算机积极拒绝，无法连接。

2023-07-19 16:26:01
Traceback (most recent call last):
  File "D:\local_repo\CTA_UI\start.py", line 441, in upload_param
    try:
  File "D:\local_repo\CTA_UI\utils\flink.py", line 54, in pull_from_UI_to_market
    ssh.connect()
  File "D:\local_repo\CTA_UI\utils\sftp.py", line 18, in connect
    transport = paramiko.Transport((self.host,self.port))
  File "C:\Users\Han.Hao\AppData\Local\anaconda3\lib\site-packages\paramiko\transport.py", line 415, in __init__
    raise SSHException(
paramiko.ssh_exception.SSHException: Unable to connect to 39.97.106.35: [WinError 10061] 由于目标计算机积极拒绝，无法连接。

2023-07-31 19:56:53
Traceback (most recent call last):
  File "D:\local_repo\CTA_UI\start.py", line 445, in upload_param
    flink.pull_from_UI_to_market(config)
  File "D:\local_repo\CTA_UI\utils\flink.py", line 57, in pull_from_UI_to_market
    ssh.connect()
  File "D:\local_repo\CTA_UI\utils\sftp.py", line 18, in connect
    transport = paramiko.Transport((self.host,self.port))
  File "C:\Users\Han.Hao\AppData\Local\anaconda3\lib\site-packages\paramiko\transport.py", line 415, in __init__
    raise SSHException(
paramiko.ssh_exception.SSHException: Unable to connect to 39.97.106.35: [WinError 10061] 由于目标计算机积极拒绝，无法连接。

2023-07-31 19:56:54
Traceback (most recent call last):
  File "D:\local_repo\CTA_UI\start.py", line 445, in upload_param
    flink.pull_from_UI_to_market(config)
  File "D:\local_repo\CTA_UI\utils\flink.py", line 56, in pull_from_UI_to_market
    username=market_server_para['username'], pwd=market_server_para['pwd'])
KeyError: 'username'

2023-07-31 19:56:58
Traceback (most recent call last):
  File "D:\local_repo\CTA_UI\start.py", line 445, in upload_param
    flink.pull_from_UI_to_market(config)
  File "D:\local_repo\CTA_UI\utils\flink.py", line 57, in pull_from_UI_to_market
    ssh.connect()
  File "D:\local_repo\CTA_UI\utils\sftp.py", line 18, in connect
    transport = paramiko.Transport((self.host,self.port))
  File "C:\Users\Han.Hao\AppData\Local\anaconda3\lib\site-packages\paramiko\transport.py", line 415, in __init__
    raise SSHException(
paramiko.ssh_exception.SSHException: Unable to connect to 39.97.106.35: [WinError 10061] 由于目标计算机积极拒绝，无法连接。

2023-07-31 19:57:01
Traceback (most recent call last):
  File "D:\local_repo\CTA_UI\start.py", line 445, in upload_param
    flink.pull_from_UI_to_market(config)
  File "D:\local_repo\CTA_UI\utils\flink.py", line 57, in pull_from_UI_to_market
    ssh.connect()
  File "D:\local_repo\CTA_UI\utils\sftp.py", line 18, in connect
    transport = paramiko.Transport((self.host,self.port))
  File "C:\Users\Han.Hao\AppData\Local\anaconda3\lib\site-packages\paramiko\transport.py", line 415, in __init__
    raise SSHException(
paramiko.ssh_exception.SSHException: Unable to connect to 39.97.106.35: [WinError 10061] 由于目标计算机积极拒绝，无法连接。

2023-07-31 19:57:05
Traceback (most recent call last):
  File "D:\local_repo\CTA_UI\start.py", line 445, in upload_param
    flink.pull_from_UI_to_market(config)
  File "D:\local_repo\CTA_UI\utils\flink.py", line 57, in pull_from_UI_to_market
    ssh.connect()
  File "D:\local_repo\CTA_UI\utils\sftp.py", line 18, in connect
    transport = paramiko.Transport((self.host,self.port))
  File "C:\Users\Han.Hao\AppData\Local\anaconda3\lib\site-packages\paramiko\transport.py", line 415, in __init__
    raise SSHException(
paramiko.ssh_exception.SSHException: Unable to connect to 39.97.106.35: [WinError 10061] 由于目标计算机积极拒绝，无法连接。

2023-07-31 20:13:59
Traceback (most recent call last):
  File "D:\local_repo\CTA_UI\start.py", line 445, in upload_param
    flink.pull_from_UI_to_market(config)
  File "D:\local_repo\CTA_UI\utils\flink.py", line 63, in pull_from_UI_to_market
    ssh.connect()
  File "D:\local_repo\CTA_UI\utils\sftp.py", line 18, in connect
    transport = paramiko.Transport((self.host,self.port))
  File "C:\Users\Han.Hao\AppData\Local\anaconda3\lib\site-packages\paramiko\transport.py", line 415, in __init__
    raise SSHException(
paramiko.ssh_exception.SSHException: Unable to connect to 10.72.2.34: [WinError 10060] 由于连接方在一段时间后没有正确答复或连接的主机没有反应，连接尝试失败。

2023-07-31 20:14:01
Traceback (most recent call last):
  File "D:\local_repo\CTA_UI\start.py", line 445, in upload_param
    flink.pull_from_UI_to_market(config)
  File "D:\local_repo\CTA_UI\utils\flink.py", line 70, in pull_from_UI_to_market
    param_dir = os.path.join(ROOT_PATH, "params", acc, "params.csv")
UnboundLocalError: local variable 'acc' referenced before assignment

2023-07-31 20:14:03
Traceback (most recent call last):
  File "D:\local_repo\CTA_UI\start.py", line 445, in upload_param
    flink.pull_from_UI_to_market(config)
  File "D:\local_repo\CTA_UI\utils\flink.py", line 70, in pull_from_UI_to_market
    param_dir = os.path.join(ROOT_PATH, "params", acc, "params.csv")
UnboundLocalError: local variable 'acc' referenced before assignment

2023-07-31 20:14:04
Traceback (most recent call last):
  File "D:\local_repo\CTA_UI\start.py", line 445, in upload_param
    flink.pull_from_UI_to_market(config)
  File "D:\local_repo\CTA_UI\utils\flink.py", line 70, in pull_from_UI_to_market
    param_dir = os.path.join(ROOT_PATH, "params", acc, "params.csv")
UnboundLocalError: local variable 'acc' referenced before assignment

2023-07-31 20:14:08
Traceback (most recent call last):
  File "D:\local_repo\CTA_UI\start.py", line 445, in upload_param
    flink.pull_from_UI_to_market(config)
  File "D:\local_repo\CTA_UI\utils\flink.py", line 79, in pull_from_UI_to_market
    ssh.connect()
  File "D:\local_repo\CTA_UI\utils\sftp.py", line 18, in connect
    transport = paramiko.Transport((self.host,self.port))
  File "C:\Users\Han.Hao\AppData\Local\anaconda3\lib\site-packages\paramiko\transport.py", line 415, in __init__
    raise SSHException(
paramiko.ssh_exception.SSHException: Unable to connect to 39.97.106.35: [WinError 10061] 由于目标计算机积极拒绝，无法连接。

2023-07-31 20:21:10
Traceback (most recent call last):
  File "D:\local_repo\CTA_UI\start.py", line 445, in upload_param
    flink.pull_from_UI_to_market(config)
  File "D:\local_repo\CTA_UI\utils\flink.py", line 63, in pull_from_UI_to_market
    ssh.connect()
  File "D:\local_repo\CTA_UI\utils\sftp.py", line 18, in connect
    transport = paramiko.Transport((self.host,self.port))
  File "C:\Users\Han.Hao\AppData\Local\anaconda3\lib\site-packages\paramiko\transport.py", line 415, in __init__
    raise SSHException(
paramiko.ssh_exception.SSHException: Unable to connect to 10.72.2.34: [WinError 10060] 由于连接方在一段时间后没有正确答复或连接的主机没有反应，连接尝试失败。

2023-07-31 20:21:12
Traceback (most recent call last):
  File "D:\local_repo\CTA_UI\start.py", line 445, in upload_param
    flink.pull_from_UI_to_market(config)
  File "D:\local_repo\CTA_UI\utils\flink.py", line 67, in pull_from_UI_to_market
    dest_acc_dir = tradeDirList[idx]
NameError: name 'tradeDirList' is not defined

2023-07-31 20:21:14
Traceback (most recent call last):
  File "D:\local_repo\CTA_UI\start.py", line 445, in upload_param
    flink.pull_from_UI_to_market(config)
  File "D:\local_repo\CTA_UI\utils\flink.py", line 67, in pull_from_UI_to_market
    dest_acc_dir = tradeDirList[idx]
NameError: name 'tradeDirList' is not defined

2023-07-31 20:21:15
Traceback (most recent call last):
  File "D:\local_repo\CTA_UI\start.py", line 445, in upload_param
    flink.pull_from_UI_to_market(config)
  File "D:\local_repo\CTA_UI\utils\flink.py", line 67, in pull_from_UI_to_market
    dest_acc_dir = tradeDirList[idx]
NameError: name 'tradeDirList' is not defined

2023-07-31 20:21:19
Traceback (most recent call last):
  File "D:\local_repo\CTA_UI\start.py", line 445, in upload_param
    flink.pull_from_UI_to_market(config)
  File "D:\local_repo\CTA_UI\utils\flink.py", line 80, in pull_from_UI_to_market
    ssh.connect()
  File "D:\local_repo\CTA_UI\utils\sftp.py", line 18, in connect
    transport = paramiko.Transport((self.host,self.port))
  File "C:\Users\Han.Hao\AppData\Local\anaconda3\lib\site-packages\paramiko\transport.py", line 415, in __init__
    raise SSHException(
paramiko.ssh_exception.SSHException: Unable to connect to 39.97.106.35: [WinError 10061] 由于目标计算机积极拒绝，无法连接。

2023-07-31 20:22:52
Traceback (most recent call last):
  File "D:\local_repo\CTA_UI\start.py", line 445, in upload_param
    flink.pull_from_UI_to_market(config)
  File "D:\local_repo\CTA_UI\utils\flink.py", line 63, in pull_from_UI_to_market
    ssh.connect()
  File "D:\local_repo\CTA_UI\utils\sftp.py", line 18, in connect
    transport = paramiko.Transport((self.host,self.port))
  File "C:\Users\Han.Hao\AppData\Local\anaconda3\lib\site-packages\paramiko\transport.py", line 415, in __init__
    raise SSHException(
paramiko.ssh_exception.SSHException: Unable to connect to 10.72.2.34: [WinError 10060] 由于连接方在一段时间后没有正确答复或连接的主机没有反应，连接尝试失败。

2023-07-31 20:23:01
Traceback (most recent call last):
  File "D:\local_repo\CTA_UI\start.py", line 445, in upload_param
    flink.pull_from_UI_to_market(config)
  File "D:\local_repo\CTA_UI\utils\flink.py", line 80, in pull_from_UI_to_market
    ssh.connect()
  File "D:\local_repo\CTA_UI\utils\sftp.py", line 18, in connect
    transport = paramiko.Transport((self.host,self.port))
  File "C:\Users\Han.Hao\AppData\Local\anaconda3\lib\site-packages\paramiko\transport.py", line 415, in __init__
    raise SSHException(
paramiko.ssh_exception.SSHException: Unable to connect to 39.97.106.35: [WinError 10061] 由于目标计算机积极拒绝，无法连接。

2023-07-31 20:24:41
Traceback (most recent call last):
  File "D:\local_repo\CTA_UI\start.py", line 445, in upload_param
    flink.pull_from_UI_to_market(config)
  File "D:\local_repo\CTA_UI\utils\flink.py", line 63, in pull_from_UI_to_market
    ssh.connect()
  File "D:\local_repo\CTA_UI\utils\sftp.py", line 18, in connect
    transport = paramiko.Transport((self.host,self.port))
  File "C:\Users\Han.Hao\AppData\Local\anaconda3\lib\site-packages\paramiko\transport.py", line 415, in __init__
    raise SSHException(
paramiko.ssh_exception.SSHException: Unable to connect to 10.72.2.34: [WinError 10060] 由于连接方在一段时间后没有正确答复或连接的主机没有反应，连接尝试失败。

2023-07-31 20:24:43
Traceback (most recent call last):
  File "D:\local_repo\CTA_UI\start.py", line 445, in upload_param
    flink.pull_from_UI_to_market(config)
  File "D:\local_repo\CTA_UI\utils\flink.py", line 72, in pull_from_UI_to_market
    ssh.upload(param_dir, os.path.join(dest_acc_dir, "params.csv"))
  File "D:\local_repo\CTA_UI\utils\sftp.py", line 30, in upload
    sftp.put(local_path, target_path)
  File "C:\Users\Han.Hao\AppData\Local\anaconda3\lib\site-packages\paramiko\sftp_client.py", line 759, in put
    return self.putfo(fl, remotepath, file_size, callback, confirm)
  File "C:\Users\Han.Hao\AppData\Local\anaconda3\lib\site-packages\paramiko\sftp_client.py", line 714, in putfo
    with self.file(remotepath, "wb") as fr:
  File "C:\Users\Han.Hao\AppData\Local\anaconda3\lib\site-packages\paramiko\sftp_client.py", line 372, in open
    t, msg = self._request(CMD_OPEN, filename, imode, attrblock)
  File "C:\Users\Han.Hao\AppData\Local\anaconda3\lib\site-packages\paramiko\sftp_client.py", line 822, in _request
    return self._read_response(num)
  File "C:\Users\Han.Hao\AppData\Local\anaconda3\lib\site-packages\paramiko\sftp_client.py", line 874, in _read_response
    self._convert_status(msg)
  File "C:\Users\Han.Hao\AppData\Local\anaconda3\lib\site-packages\paramiko\sftp_client.py", line 907, in _convert_status
    raise IOError(text)
OSError: Failure

2023-07-31 20:24:51
Traceback (most recent call last):
  File "D:\local_repo\CTA_UI\start.py", line 445, in upload_param
    flink.pull_from_UI_to_market(config)
  File "D:\local_repo\CTA_UI\utils\flink.py", line 80, in pull_from_UI_to_market
    ssh.connect()
  File "D:\local_repo\CTA_UI\utils\sftp.py", line 18, in connect
    transport = paramiko.Transport((self.host,self.port))
  File "C:\Users\Han.Hao\AppData\Local\anaconda3\lib\site-packages\paramiko\transport.py", line 415, in __init__
    raise SSHException(
paramiko.ssh_exception.SSHException: Unable to connect to 39.97.106.35: [WinError 10061] 由于目标计算机积极拒绝，无法连接。

2023-07-31 20:25:37
Traceback (most recent call last):
  File "D:\local_repo\CTA_UI\start.py", line 445, in upload_param
    flink.pull_from_UI_to_market(config)
  File "D:\local_repo\CTA_UI\utils\flink.py", line 63, in pull_from_UI_to_market
    ssh.connect()
  File "D:\local_repo\CTA_UI\utils\sftp.py", line 18, in connect
    transport = paramiko.Transport((self.host,self.port))
  File "C:\Users\Han.Hao\AppData\Local\anaconda3\lib\site-packages\paramiko\transport.py", line 415, in __init__
    raise SSHException(
paramiko.ssh_exception.SSHException: Unable to connect to 10.72.2.34: [WinError 10060] 由于连接方在一段时间后没有正确答复或连接的主机没有反应，连接尝试失败。

2023-07-31 20:25:47
Traceback (most recent call last):
  File "D:\local_repo\CTA_UI\start.py", line 445, in upload_param
    flink.pull_from_UI_to_market(config)
  File "D:\local_repo\CTA_UI\utils\flink.py", line 80, in pull_from_UI_to_market
    ssh.connect()
  File "D:\local_repo\CTA_UI\utils\sftp.py", line 18, in connect
    transport = paramiko.Transport((self.host,self.port))
  File "C:\Users\Han.Hao\AppData\Local\anaconda3\lib\site-packages\paramiko\transport.py", line 415, in __init__
    raise SSHException(
paramiko.ssh_exception.SSHException: Unable to connect to 39.97.106.35: [WinError 10061] 由于目标计算机积极拒绝，无法连接。

2023-07-31 21:36:38
Traceback (most recent call last):
  File "D:\local_repo\CTA_UI\start.py", line 445, in upload_param
    flink.pull_from_UI_to_market(config)
  File "D:\local_repo\CTA_UI\utils\flink.py", line 63, in pull_from_UI_to_market
    ssh.connect()
  File "D:\local_repo\CTA_UI\utils\sftp.py", line 18, in connect
    transport = paramiko.Transport((self.host,self.port))
  File "C:\Users\Han.Hao\AppData\Local\anaconda3\lib\site-packages\paramiko\transport.py", line 415, in __init__
    raise SSHException(
paramiko.ssh_exception.SSHException: Unable to connect to 10.72.2.34: [WinError 10060] 由于连接方在一段时间后没有正确答复或连接的主机没有反应，连接尝试失败。

2023-07-31 21:36:48
Traceback (most recent call last):
  File "D:\local_repo\CTA_UI\start.py", line 445, in upload_param
    flink.pull_from_UI_to_market(config)
  File "D:\local_repo\CTA_UI\utils\flink.py", line 80, in pull_from_UI_to_market
    ssh.connect()
  File "D:\local_repo\CTA_UI\utils\sftp.py", line 18, in connect
    transport = paramiko.Transport((self.host,self.port))
  File "C:\Users\Han.Hao\AppData\Local\anaconda3\lib\site-packages\paramiko\transport.py", line 415, in __init__
    raise SSHException(
paramiko.ssh_exception.SSHException: Unable to connect to 39.97.106.35: [WinError 10061] 由于目标计算机积极拒绝，无法连接。

2023-07-31 21:45:02
Traceback (most recent call last):
  File "D:\local_repo\CTA_UI\start.py", line 445, in upload_param
    flink.pull_from_UI_to_market(config)
  File "D:\local_repo\CTA_UI\utils\flink.py", line 63, in pull_from_UI_to_market
    ssh.connect()
  File "D:\local_repo\CTA_UI\utils\sftp.py", line 18, in connect
    transport = paramiko.Transport((self.host,self.port))
  File "C:\Users\Han.Hao\AppData\Local\anaconda3\lib\site-packages\paramiko\transport.py", line 415, in __init__
    raise SSHException(
paramiko.ssh_exception.SSHException: Unable to connect to 10.72.2.34: [WinError 10060] 由于连接方在一段时间后没有正确答复或连接的主机没有反应，连接尝试失败。

2023-07-31 21:45:12
Traceback (most recent call last):
  File "D:\local_repo\CTA_UI\start.py", line 445, in upload_param
    flink.pull_from_UI_to_market(config)
  File "D:\local_repo\CTA_UI\utils\flink.py", line 80, in pull_from_UI_to_market
    ssh.connect()
  File "D:\local_repo\CTA_UI\utils\sftp.py", line 18, in connect
    transport = paramiko.Transport((self.host,self.port))
  File "C:\Users\Han.Hao\AppData\Local\anaconda3\lib\site-packages\paramiko\transport.py", line 415, in __init__
    raise SSHException(
paramiko.ssh_exception.SSHException: Unable to connect to 39.97.106.35: [WinError 10061] 由于目标计算机积极拒绝，无法连接。

2023-08-01 00:38:26
Traceback (most recent call last):
  File "D:\local_repo\CTA_UI\start.py", line 445, in upload_param
    flink.pull_from_UI_to_market(config)
  File "D:\local_repo\CTA_UI\utils\flink.py", line 63, in pull_from_UI_to_market
    ssh.connect()
  File "D:\local_repo\CTA_UI\utils\sftp.py", line 18, in connect
    transport = paramiko.Transport((self.host,self.port))
  File "C:\Users\Han.Hao\AppData\Local\anaconda3\lib\site-packages\paramiko\transport.py", line 415, in __init__
    raise SSHException(
paramiko.ssh_exception.SSHException: Unable to connect to 10.72.2.34: [WinError 10060] 由于连接方在一段时间后没有正确答复或连接的主机没有反应，连接尝试失败。

2023-08-01 00:38:36
Traceback (most recent call last):
  File "D:\local_repo\CTA_UI\start.py", line 445, in upload_param
    flink.pull_from_UI_to_market(config)
  File "D:\local_repo\CTA_UI\utils\flink.py", line 80, in pull_from_UI_to_market
    ssh.connect()
  File "D:\local_repo\CTA_UI\utils\sftp.py", line 18, in connect
    transport = paramiko.Transport((self.host,self.port))
  File "C:\Users\Han.Hao\AppData\Local\anaconda3\lib\site-packages\paramiko\transport.py", line 415, in __init__
    raise SSHException(
paramiko.ssh_exception.SSHException: Unable to connect to 39.97.106.35: [WinError 10061] 由于目标计算机积极拒绝，无法连接。

2023-08-01 09:02:45
Traceback (most recent call last):
  File "D:\local_repo\CTA_UI\start.py", line 445, in upload_param
    flink.pull_from_UI_to_market(config)
  File "D:\local_repo\CTA_UI\utils\flink.py", line 63, in pull_from_UI_to_market
    ssh.connect()
  File "D:\local_repo\CTA_UI\utils\sftp.py", line 18, in connect
    transport = paramiko.Transport((self.host,self.port))
  File "C:\Users\Han.Hao\AppData\Local\anaconda3\lib\site-packages\paramiko\transport.py", line 415, in __init__
    raise SSHException(
paramiko.ssh_exception.SSHException: Unable to connect to 10.72.2.34: [WinError 10060] 由于连接方在一段时间后没有正确答复或连接的主机没有反应，连接尝试失败。

2023-08-01 09:02:55
Traceback (most recent call last):
  File "D:\local_repo\CTA_UI\start.py", line 445, in upload_param
    flink.pull_from_UI_to_market(config)
  File "D:\local_repo\CTA_UI\utils\flink.py", line 80, in pull_from_UI_to_market
    ssh.connect()
  File "D:\local_repo\CTA_UI\utils\sftp.py", line 18, in connect
    transport = paramiko.Transport((self.host,self.port))
  File "C:\Users\Han.Hao\AppData\Local\anaconda3\lib\site-packages\paramiko\transport.py", line 415, in __init__
    raise SSHException(
paramiko.ssh_exception.SSHException: Unable to connect to 39.97.106.35: [WinError 10061] 由于目标计算机积极拒绝，无法连接。

2023-08-01 09:10:03
Traceback (most recent call last):
  File "D:\local_repo\CTA_UI\start.py", line 445, in upload_param
    flink.pull_from_UI_to_market(config)
  File "D:\local_repo\CTA_UI\utils\flink.py", line 63, in pull_from_UI_to_market
    ssh.connect()
  File "D:\local_repo\CTA_UI\utils\sftp.py", line 18, in connect
    transport = paramiko.Transport((self.host,self.port))
  File "C:\Users\Han.Hao\AppData\Local\anaconda3\lib\site-packages\paramiko\transport.py", line 415, in __init__
    raise SSHException(
paramiko.ssh_exception.SSHException: Unable to connect to 10.72.2.34: [WinError 10060] 由于连接方在一段时间后没有正确答复或连接的主机没有反应，连接尝试失败。

2023-08-01 09:10:12
Traceback (most recent call last):
  File "D:\local_repo\CTA_UI\start.py", line 445, in upload_param
    flink.pull_from_UI_to_market(config)
  File "D:\local_repo\CTA_UI\utils\flink.py", line 80, in pull_from_UI_to_market
    ssh.connect()
  File "D:\local_repo\CTA_UI\utils\sftp.py", line 18, in connect
    transport = paramiko.Transport((self.host,self.port))
  File "C:\Users\Han.Hao\AppData\Local\anaconda3\lib\site-packages\paramiko\transport.py", line 415, in __init__
    raise SSHException(
paramiko.ssh_exception.SSHException: Unable to connect to 39.97.106.35: [WinError 10061] 由于目标计算机积极拒绝，无法连接。

2023-08-01 09:34:05
Traceback (most recent call last):
  File "D:\local_repo\CTA_UI\start.py", line 445, in upload_param
    flink.pull_from_UI_to_market(config)
  File "D:\local_repo\CTA_UI\utils\flink.py", line 63, in pull_from_UI_to_market
    ssh.connect()
  File "D:\local_repo\CTA_UI\utils\sftp.py", line 18, in connect
    transport = paramiko.Transport((self.host,self.port))
  File "C:\Users\Han.Hao\AppData\Local\anaconda3\lib\site-packages\paramiko\transport.py", line 415, in __init__
    raise SSHException(
paramiko.ssh_exception.SSHException: Unable to connect to 10.72.2.34: [WinError 10060] 由于连接方在一段时间后没有正确答复或连接的主机没有反应，连接尝试失败。

2023-08-01 09:34:15
Traceback (most recent call last):
  File "D:\local_repo\CTA_UI\start.py", line 445, in upload_param
    flink.pull_from_UI_to_market(config)
  File "D:\local_repo\CTA_UI\utils\flink.py", line 80, in pull_from_UI_to_market
    ssh.connect()
  File "D:\local_repo\CTA_UI\utils\sftp.py", line 18, in connect
    transport = paramiko.Transport((self.host,self.port))
  File "C:\Users\Han.Hao\AppData\Local\anaconda3\lib\site-packages\paramiko\transport.py", line 415, in __init__
    raise SSHException(
paramiko.ssh_exception.SSHException: Unable to connect to 39.97.106.35: [WinError 10061] 由于目标计算机积极拒绝，无法连接。

2023-08-01 09:40:44
Traceback (most recent call last):
  File "D:\local_repo\CTA_UI\start.py", line 445, in upload_param
    flink.pull_from_UI_to_market(config)
  File "D:\local_repo\CTA_UI\utils\flink.py", line 63, in pull_from_UI_to_market
    ssh.connect()
  File "D:\local_repo\CTA_UI\utils\sftp.py", line 18, in connect
    transport = paramiko.Transport((self.host,self.port))
  File "C:\Users\Han.Hao\AppData\Local\anaconda3\lib\site-packages\paramiko\transport.py", line 415, in __init__
    raise SSHException(
paramiko.ssh_exception.SSHException: Unable to connect to 10.72.2.34: [WinError 10060] 由于连接方在一段时间后没有正确答复或连接的主机没有反应，连接尝试失败。

2023-08-01 09:40:53
Traceback (most recent call last):
  File "D:\local_repo\CTA_UI\start.py", line 445, in upload_param
    flink.pull_from_UI_to_market(config)
  File "D:\local_repo\CTA_UI\utils\flink.py", line 80, in pull_from_UI_to_market
    ssh.connect()
  File "D:\local_repo\CTA_UI\utils\sftp.py", line 18, in connect
    transport = paramiko.Transport((self.host,self.port))
  File "C:\Users\Han.Hao\AppData\Local\anaconda3\lib\site-packages\paramiko\transport.py", line 415, in __init__
    raise SSHException(
paramiko.ssh_exception.SSHException: Unable to connect to 39.97.106.35: [WinError 10061] 由于目标计算机积极拒绝，无法连接。

2023-08-01 09:42:56
Traceback (most recent call last):
  File "D:\local_repo\CTA_UI\start.py", line 445, in upload_param
    flink.pull_from_UI_to_market(config)
  File "D:\local_repo\CTA_UI\utils\flink.py", line 63, in pull_from_UI_to_market
    ssh.connect()
  File "D:\local_repo\CTA_UI\utils\sftp.py", line 18, in connect
    transport = paramiko.Transport((self.host,self.port))
  File "C:\Users\Han.Hao\AppData\Local\anaconda3\lib\site-packages\paramiko\transport.py", line 415, in __init__
    raise SSHException(
paramiko.ssh_exception.SSHException: Unable to connect to 10.72.2.34: [WinError 10060] 由于连接方在一段时间后没有正确答复或连接的主机没有反应，连接尝试失败。

2023-08-01 09:43:06
Traceback (most recent call last):
  File "D:\local_repo\CTA_UI\start.py", line 445, in upload_param
    flink.pull_from_UI_to_market(config)
  File "D:\local_repo\CTA_UI\utils\flink.py", line 80, in pull_from_UI_to_market
    ssh.connect()
  File "D:\local_repo\CTA_UI\utils\sftp.py", line 18, in connect
    transport = paramiko.Transport((self.host,self.port))
  File "C:\Users\Han.Hao\AppData\Local\anaconda3\lib\site-packages\paramiko\transport.py", line 415, in __init__
    raise SSHException(
paramiko.ssh_exception.SSHException: Unable to connect to 39.97.106.35: [WinError 10061] 由于目标计算机积极拒绝，无法连接。

2023-08-01 09:52:05
Traceback (most recent call last):
  File "D:\local_repo\CTA_UI\start.py", line 445, in upload_param
    flink.pull_from_UI_to_market(config)
  File "D:\local_repo\CTA_UI\utils\flink.py", line 63, in pull_from_UI_to_market
    ssh.connect()
  File "D:\local_repo\CTA_UI\utils\sftp.py", line 18, in connect
    transport = paramiko.Transport((self.host,self.port))
  File "C:\Users\Han.Hao\AppData\Local\anaconda3\lib\site-packages\paramiko\transport.py", line 415, in __init__
    raise SSHException(
paramiko.ssh_exception.SSHException: Unable to connect to 10.72.2.34: [WinError 10060] 由于连接方在一段时间后没有正确答复或连接的主机没有反应，连接尝试失败。

2023-08-01 09:52:14
Traceback (most recent call last):
  File "D:\local_repo\CTA_UI\start.py", line 445, in upload_param
    flink.pull_from_UI_to_market(config)
  File "D:\local_repo\CTA_UI\utils\flink.py", line 80, in pull_from_UI_to_market
    ssh.connect()
  File "D:\local_repo\CTA_UI\utils\sftp.py", line 18, in connect
    transport = paramiko.Transport((self.host,self.port))
  File "C:\Users\Han.Hao\AppData\Local\anaconda3\lib\site-packages\paramiko\transport.py", line 415, in __init__
    raise SSHException(
paramiko.ssh_exception.SSHException: Unable to connect to 39.97.106.35: [WinError 10061] 由于目标计算机积极拒绝，无法连接。

2023-08-01 09:53:57
Traceback (most recent call last):
  File "D:\local_repo\CTA_UI\start.py", line 445, in upload_param
    flink.pull_from_UI_to_market(config)
  File "D:\local_repo\CTA_UI\utils\flink.py", line 63, in pull_from_UI_to_market
    ssh.connect()
  File "D:\local_repo\CTA_UI\utils\sftp.py", line 18, in connect
    transport = paramiko.Transport((self.host,self.port))
  File "C:\Users\Han.Hao\AppData\Local\anaconda3\lib\site-packages\paramiko\transport.py", line 415, in __init__
    raise SSHException(
paramiko.ssh_exception.SSHException: Unable to connect to 10.72.2.34: [WinError 10060] 由于连接方在一段时间后没有正确答复或连接的主机没有反应，连接尝试失败。

2023-08-01 09:54:07
Traceback (most recent call last):
  File "D:\local_repo\CTA_UI\start.py", line 445, in upload_param
    flink.pull_from_UI_to_market(config)
  File "D:\local_repo\CTA_UI\utils\flink.py", line 80, in pull_from_UI_to_market
    ssh.connect()
  File "D:\local_repo\CTA_UI\utils\sftp.py", line 18, in connect
    transport = paramiko.Transport((self.host,self.port))
  File "C:\Users\Han.Hao\AppData\Local\anaconda3\lib\site-packages\paramiko\transport.py", line 415, in __init__
    raise SSHException(
paramiko.ssh_exception.SSHException: Unable to connect to 39.97.106.35: [WinError 10061] 由于目标计算机积极拒绝，无法连接。

2023-08-01 09:57:33
Traceback (most recent call last):
  File "D:\local_repo\CTA_UI\start.py", line 445, in upload_param
    flink.pull_from_UI_to_market(config)
  File "D:\local_repo\CTA_UI\utils\flink.py", line 63, in pull_from_UI_to_market
    ssh.connect()
  File "D:\local_repo\CTA_UI\utils\sftp.py", line 18, in connect
    transport = paramiko.Transport((self.host,self.port))
  File "C:\Users\Han.Hao\AppData\Local\anaconda3\lib\site-packages\paramiko\transport.py", line 415, in __init__
    raise SSHException(
paramiko.ssh_exception.SSHException: Unable to connect to 10.72.2.34: [WinError 10060] 由于连接方在一段时间后没有正确答复或连接的主机没有反应，连接尝试失败。

2023-08-01 09:57:43
Traceback (most recent call last):
  File "D:\local_repo\CTA_UI\start.py", line 445, in upload_param
    flink.pull_from_UI_to_market(config)
  File "D:\local_repo\CTA_UI\utils\flink.py", line 80, in pull_from_UI_to_market
    ssh.connect()
  File "D:\local_repo\CTA_UI\utils\sftp.py", line 18, in connect
    transport = paramiko.Transport((self.host,self.port))
  File "C:\Users\Han.Hao\AppData\Local\anaconda3\lib\site-packages\paramiko\transport.py", line 415, in __init__
    raise SSHException(
paramiko.ssh_exception.SSHException: Unable to connect to 39.97.106.35: [WinError 10061] 由于目标计算机积极拒绝，无法连接。

2023-08-01 09:59:13
Traceback (most recent call last):
  File "D:\local_repo\CTA_UI\start.py", line 445, in upload_param
    flink.pull_from_UI_to_market(config)
  File "D:\local_repo\CTA_UI\utils\flink.py", line 63, in pull_from_UI_to_market
    ssh.connect()
  File "D:\local_repo\CTA_UI\utils\sftp.py", line 18, in connect
    transport = paramiko.Transport((self.host,self.port))
  File "C:\Users\Han.Hao\AppData\Local\anaconda3\lib\site-packages\paramiko\transport.py", line 415, in __init__
    raise SSHException(
paramiko.ssh_exception.SSHException: Unable to connect to 10.72.2.34: [WinError 10060] 由于连接方在一段时间后没有正确答复或连接的主机没有反应，连接尝试失败。

2023-08-01 09:59:23
Traceback (most recent call last):
  File "D:\local_repo\CTA_UI\start.py", line 445, in upload_param
    flink.pull_from_UI_to_market(config)
  File "D:\local_repo\CTA_UI\utils\flink.py", line 80, in pull_from_UI_to_market
    ssh.connect()
  File "D:\local_repo\CTA_UI\utils\sftp.py", line 18, in connect
    transport = paramiko.Transport((self.host,self.port))
  File "C:\Users\Han.Hao\AppData\Local\anaconda3\lib\site-packages\paramiko\transport.py", line 415, in __init__
    raise SSHException(
paramiko.ssh_exception.SSHException: Unable to connect to 39.97.106.35: [WinError 10061] 由于目标计算机积极拒绝，无法连接。

2023-08-01 10:00:43
Traceback (most recent call last):
  File "D:\local_repo\CTA_UI\start.py", line 445, in upload_param
    flink.pull_from_UI_to_market(config)
  File "D:\local_repo\CTA_UI\utils\flink.py", line 63, in pull_from_UI_to_market
    ssh.connect()
  File "D:\local_repo\CTA_UI\utils\sftp.py", line 18, in connect
    transport = paramiko.Transport((self.host,self.port))
  File "C:\Users\Han.Hao\AppData\Local\anaconda3\lib\site-packages\paramiko\transport.py", line 415, in __init__
    raise SSHException(
paramiko.ssh_exception.SSHException: Unable to connect to 10.72.2.34: [WinError 10060] 由于连接方在一段时间后没有正确答复或连接的主机没有反应，连接尝试失败。

2023-08-01 10:00:52
Traceback (most recent call last):
  File "D:\local_repo\CTA_UI\start.py", line 445, in upload_param
    flink.pull_from_UI_to_market(config)
  File "D:\local_repo\CTA_UI\utils\flink.py", line 80, in pull_from_UI_to_market
    ssh.connect()
  File "D:\local_repo\CTA_UI\utils\sftp.py", line 18, in connect
    transport = paramiko.Transport((self.host,self.port))
  File "C:\Users\Han.Hao\AppData\Local\anaconda3\lib\site-packages\paramiko\transport.py", line 415, in __init__
    raise SSHException(
paramiko.ssh_exception.SSHException: Unable to connect to 39.97.106.35: [WinError 10061] 由于目标计算机积极拒绝，无法连接。

2023-08-01 10:08:01
Traceback (most recent call last):
  File "D:\local_repo\CTA_UI\start.py", line 445, in upload_param
    flink.pull_from_UI_to_market(config)
  File "D:\local_repo\CTA_UI\utils\flink.py", line 63, in pull_from_UI_to_market
    ssh.connect()
  File "D:\local_repo\CTA_UI\utils\sftp.py", line 18, in connect
    transport = paramiko.Transport((self.host,self.port))
  File "C:\Users\Han.Hao\AppData\Local\anaconda3\lib\site-packages\paramiko\transport.py", line 415, in __init__
    raise SSHException(
paramiko.ssh_exception.SSHException: Unable to connect to 10.72.2.34: [WinError 10060] 由于连接方在一段时间后没有正确答复或连接的主机没有反应，连接尝试失败。

2023-08-01 10:08:11
Traceback (most recent call last):
  File "D:\local_repo\CTA_UI\start.py", line 445, in upload_param
    flink.pull_from_UI_to_market(config)
  File "D:\local_repo\CTA_UI\utils\flink.py", line 80, in pull_from_UI_to_market
    ssh.connect()
  File "D:\local_repo\CTA_UI\utils\sftp.py", line 18, in connect
    transport = paramiko.Transport((self.host,self.port))
  File "C:\Users\Han.Hao\AppData\Local\anaconda3\lib\site-packages\paramiko\transport.py", line 415, in __init__
    raise SSHException(
paramiko.ssh_exception.SSHException: Unable to connect to 39.97.106.35: [WinError 10061] 由于目标计算机积极拒绝，无法连接。

